Workbook
Name R_강원: 목록!$B$1:$B$18
Name R_경기: 목록!$C$1:$C$31
Name R_경남: 목록!$D$1:$D$18
Name R_경북: 목록!$E$1:$E$21
Name R_광주: 목록!$F$1:$F$5
Name R_대구: 목록!$G$1:$G$9
Name R_대전: 목록!$H$1:$H$5
Name R_부산: 목록!$I$1:$I$16
Name R_서울: 목록!$J$1:$J$25
Name R_세종: 목록!$K$1:$K$1
Name R_울산: 목록!$L$1:$L$5
Name R_인천: 목록!$M$1:$M$10
Name R_전남: 목록!$N$1:$N$22
Name R_전북: 목록!$O$1:$O$14
Name R_제주: 목록!$P$1:$P$2
Name R_충남: 목록!$Q$1:$Q$15
Name R_충북: 목록!$R$1:$R$11
Name S_강원_강릉시: 목록!$S$1:$S$8
Name S_강원_고성군: 목록!$T$1:$T$2
Name S_강원_동해시: 목록!$U$1:$U$5
Name S_강원_삼척시: 목록!$V$1:$V$6
Name S_강원_속초시: 목록!$W$1:$W$3
Name S_강원_양구군: 목록!$X$1:$X$3
Name S_강원_양양군: 목록!$Y$1:$Y$1
Name S_강원_영월군: 목록!$Z$1:$Z$5
Name S_강원_원주시: 목록!$AA$1:$AA$12
Name S_강원_인제군: 목록!$AB$1:$AB$4
Name S_강원_정선군: 목록!$AC$1:$AC$6
Name S_강원_철원군: 목록!$AD$1:$AD$4
Name S_강원_춘천시: 목록!$AE$1:$AE$8
Name S_강원_태백시: 목록!$AF$1:$AF$3
Name S_강원_평창군: 목록!$AG$1:$AG$5
Name S_강원_홍천군: 목록!$AH$1:$AH$4
Name S_강원_화천군: 목록!$AI$1:$AI$3
Name S_강원_횡성군: 목록!$AJ$1:$AJ$6
Name S_경기_가평군: 목록!$AK$1:$AK$5
Name S_경기_고양시: 목록!$AL$1:$AL$32
Name S_경기_과천시: 목록!$AM$1:$AM$4
Name S_경기_광명시: 목록!$AN$1:$AN$9
Name S_경기_광주시: 목록!$AO$1:$AO$7
Name S_경기_구리시: 목록!$AP$1:$AP$7
Name S_경기_군포시: 목록!$AQ$1:$AQ$6
Name S_경기_김포시: 목록!$AR$1:$AR$15
Name S_경기_남양주시: 목록!$AS$1:$AS$20
Name S_경기_동두천시: 목록!$AT$1:$AT$5
Name S_경기_부천시: 목록!$AU$1:$AU$23
Name S_경기_성남시: 목록!$AV$1:$AV$28
Name S_경기_수원시: 목록!$AW$1:$AW$34
Name S_경기_시흥시: 목록!$AX$1:$AX$13
Name S_경기_안산시: 목록!$AY$1:$AY$18
Name S_경기_안성시: 목록!$AZ$1:$AZ$6
Name S_경기_안양시: 목록!$BA$1:$BA$14
Name S_경기_양주시: 목록!$BB$1:$BB$7
Name S_경기_양평군: 목록!$BC$1:$BC$7
Name S_경기_여주시: 목록!$BD$1:$BD$7
Name S_경기_연천군: 목록!$BE$1:$BE$2
Name S_경기_오산시: 목록!$BF$1:$BF$7
Name S_경기_용인시: 목록!$BG$1:$BG$30
Name S_경기_의왕시: 목록!$BH$1:$BH$5
Name S_경기_의정부시: 목록!$BI$1:$BI$13

Sheet 계산기
B2: 수시 배치 계산기 | V2: 비교 내신 | W2: 2.7 | Z2: 호갱노노
B3: 지원 정보 입력 | R3: 배치표 조회 (자동) | Z3: 추천대학
B4: No. | C4: 광역 | D4: 기초 | E4: 대학 | F4: 전형유형 | G4: 전형명 | H4: 모집단위명 | I4: 계열 | J4: 상세계열 | K4: 인원 | M4: 티어 | N4: 내점수 | P4: 판정 | R4: 소신 | S4: 적정 | T4: 안정 | V4: 내점수 | W4: 판정 | Z4: 수과가산 | AA4: 면접
B5: 1025 | C5: 서울 | D5: 서울 | E5: 고려대학교 | F5: 학생부종합 | G5: 계열적합전형 | H5: 경영대학 | I5: 인문 | J5: 고려계열인문1 | K5: 46 | M5: =IF(I5="","",IF(I5="인문",성적입력!$C$8,성적입력!$C$9)) -> A | N5: =성적입력!$C$15 -> 3 | P5: =IF(OR(J5="",N5="",M5=""),"",IF(N5<=T5,"안정",IF(N5<=S5,"적정",IF(N5<=R5,"소신","상향")))) -> 상향 | R5: {=IFERROR(IF(OR(J5="",M5="",F5=""),"",IF(F5="학생부종합",INDEX(종합배치표!$C:$Q,MATCH(J5,종합배치표!$B:$B,0),(MATCH(M5,{"A","B","C","D","E"},0)-1)*3+1),INDEX(교과배치표!$C:$Q,MATCH(J5,교과배치표!$B:$B,0),(MATCH(M5,{"A","B","C","D","E"},0)-1)*3+1))),"")} -> 2.95 | S5: {=IFERROR(IF(OR(J5="",M5="",F5=""),"",IF(F5="학생부종합",INDEX(종합배치표!$C:$Q,MATCH(J5,종합배치표!$B:$B,0),(MATCH(M5,{"A","B","C","D","E"},0)-1)*3+2),INDEX(교과배치표!$C:$Q,MATCH(J5,교과배치표!$B:$B,0),(MATCH(M5,{"A","B","C","D","E"},0)-1)*3+2))),"")} -> 2.55 | T5: {=IFERROR(IF(OR(J5="",M5="",F5=""),"",IF(F5="학생부종합",INDEX(종합배치표!$C:$Q,MATCH(J5,종합배치표!$B:$B,0),(MATCH(M5,{"A","B","C","D","E"},0)-1)*3+3),INDEX(교과배치표!$C:$Q,MATCH(J5,교과배치표!$B:$B,0),(MATCH(M5,{"A","B","C","D","E"},0)-1)*3+3))),"")} -> 2.25 | V5: =$W$2 -> 2.7 | W5: =IF(OR(J5="",V5="",M5=""),"",IF(V5<=T5,"안정",IF(V5<=S5,"적정",IF(V5<=R5,"소신","상향")))) -> 소신
B6: 1028 | C6: 서울 | D6: 서울 | E6: 고려대학교 | F6: 학생부종합 | G6: 계열적합전형 | H6: 경제학과 | I6: 인문 | J6: 고려계열인문1 | K6: 15 | M6: =IF(I6="","",IF(I6="인문",성적입력!$C$8,성적입력!$C$9)) -> A | N6: =성적입력!$C$15 -> 3 | P6: =IF(OR(J6="",N6="",M6=""),"",IF(N6<=T6,"안정",IF(N6<=S6,"적정",IF(N6<=R6,"소신","상향")))) -> 상향 | R6: {=IFERROR(IF(OR(J6="",M6="",F6=""),"",IF(F6="학생부종합",INDEX(종합배치표!$C:$Q,MATCH(J6,종합배치표!$B:$B,0),(MATCH(M6,{"A","B","C","D","E"},0)-1)*3+1),INDEX(교과배치표!$C:$Q,MATCH(J6,교과배치표!$B:$B,0),(MATCH(M6,{"A","B","C","D","E"},0)-1)*3+1))),"")} -> 2.95 | S6: {=IFERROR(IF(OR(J6="",M6="",F6=""),"",IF(F6="학생부종합",INDEX(종합배치표!$C:$Q,MATCH(J6,종합배치표!$B:$B,0),(MATCH(M6,{"A","B","C","D","E"},0)-1)*3+2),INDEX(교과배치표!$C:$Q,MATCH(J6,교과배치표!$B:$B,0),(MATCH(M6,{"A","B","C","D","E"},0)-1)*3+2))),"")} -> 2.55 | T6: {=IFERROR(IF(OR(J6="",M6="",F6=""),"",IF(F6="학생부종합",INDEX(종합배치표!$C:$Q,MATCH(J6,종합배치표!$B:$B,0),(MATCH(M6,{"A","B","C","D","E"},0)-1)*3+3),INDEX(교과배치표!$C:$Q,MATCH(J6,교과배치표!$B:$B,0),(MATCH(M6,{"A","B","C","D","E"},0)-1)*3+3))),"")} -> 2.25 | V6: =$W$2 -> 2.7 | W6: =IF(OR(J6="",V6="",M6=""),"",IF(V6<=T6,"안정",IF(V6<=S6,"적정",IF(V6<=R6,"소신","상향")))) -> 소신
B7: 1060 | C7: 서울 | D7: 서울 | E7: 고려대학교 | F7: 학생부종합 | G7: 계열적합전형 | H7: 미디어학부 | I7: 인문 | J7: 고려계열인문1 | K7: 8 | M7: =IF(I7="","",IF(I7="인문",성적입력!$C$8,성적입력!$C$9)) -> A | N7: =성적입력!$C$15 -> 3 | P7: =IF(OR(J7="",N7="",M7=""),"",IF(N7<=T7,"안정",IF(N7<=S7,"적정",IF(N7<=R7,"소신","상향")))) -> 상향 | R7: {=IFERROR(IF(OR(J7="",M7="",F7=""),"",IF(F7="학생부종합",INDEX(종합배치표!$C:$Q,MATCH(J7,종합배치표!$B:$B,0),(MATCH(M7,{"A","B","C","D","E"},0)-1)*3+1),INDEX(교과배치표!$C:$Q,MATCH(J7,교과배치표!$B:$B,0),(MATCH(M7,{"A","B","C","D","E"},0)-1)*3+1))),"")} -> 2.95 | S7: {=IFERROR(IF(OR(J7="",M7="",F7=""),"",IF(F7="학생부종합",INDEX(종합배치표!$C:$Q,MATCH(J7,종합배치표!$B:$B,0),(MATCH(M7,{"A","B","C","D","E"},0)-1)*3+2),INDEX(교과배치표!$C:$Q,MATCH(J7,교과배치표!$B:$B,0),(MATCH(M7,{"A","B","C","D","E"},0)-1)*3+2))),"")} -> 2.55 | T7: {=IFERROR(IF(OR(J7="",M7="",F7=""),"",IF(F7="학생부종합",INDEX(종합배치표!$C:$Q,MATCH(J7,종합배치표!$B:$B,0),(MATCH(M7,{"A","B","C","D","E"},0)-1)*3+3),INDEX(교과배치표!$C:$Q,MATCH(J7,교과배치표!$B:$B,0),(MATCH(M7,{"A","B","C","D","E"},0)-1)*3+3))),"")} -> 2.25 | V7: =$W$2 -> 2.7 | W7: =IF(OR(J7="",V7="",M7=""),"",IF(V7<=T7,"안정",IF(V7<=S7,"적정",IF(V7<=R7,"소신","상향")))) -> 소신
B8: 1113 | C8: 서울 | D8: 서울 | E8: 고려대학교 | F8: 학생부종합 | G8: 계열적합전형 | H8: 식품자원경제학과 | I8: 인문 | J8: 고려계열인문1 | K8: 6 | M8: =IF(I8="","",IF(I8="인문",성적입력!$C$8,성적입력!$C$9)) -> A | N8: =성적입력!$C$15 -> 3 | P8: =IF(OR(J8="",N8="",M8=""),"",IF(N8<=T8,"안정",IF(N8<=S8,"적정",IF(N8<=R8,"소신","상향")))) -> 상향 | R8: {=IFERROR(IF(OR(J8="",M8="",F8=""),"",IF(F8="학생부종합",INDEX(종합배치표!$C:$Q,MATCH(J8,종합배치표!$B:$B,0),(MATCH(M8,{"A","B","C","D","E"},0)-1)*3+1),INDEX(교과배치표!$C:$Q,MATCH(J8,교과배치표!$B:$B,0),(MATCH(M8,{"A","B","C","D","E"},0)-1)*3+1))),"")} -> 2.95 | S8: {=IFERROR(IF(OR(J8="",M8="",F8=""),"",IF(F8="학생부종합",INDEX(종합배치표!$C:$Q,MATCH(J8,종합배치표!$B:$B,0),(MATCH(M8,{"A","B","C","D","E"},0)-1)*3+2),INDEX(교과배치표!$C:$Q,MATCH(J8,교과배치표!$B:$B,0),(MATCH(M8,{"A","B","C","D","E"},0)-1)*3+2))),"")} -> 2.55 | T8: {=IFERROR(IF(OR(J8="",M8="",F8=""),"",IF(F8="학생부종합",INDEX(종합배치표!$C:$Q,MATCH(J8,종합배치표!$B:$B,0),(MATCH(M8,{"A","B","C","D","E"},0)-1)*3+3),INDEX(교과배치표!$C:$Q,MATCH(J8,교과배치표!$B:$B,0),(MATCH(M8,{"A","B","C","D","E"},0)-1)*3+3))),"")} -> 2.25 | V8: =$W$2 -> 2.7 | W8: =IF(OR(J8="",V8="",M8=""),"",IF(V8<=T8,"안정",IF(V8<=S8,"적정",IF(V8<=R8,"소신","상향")))) -> 소신
B9: 1119 | C9: 서울 | D9: 서울 | E9: 고려대학교 | F9: 학생부종합 | G9: 계열적합전형 | H9: 심리학부 | I9: 인문 | J9: 고려계열인문1 | K9: 5 | M9: =IF(I9="","",IF(I9="인문",성적입력!$C$8,성적입력!$C$9)) -> A | N9: =성적입력!$C$15 -> 3 | P9: =IF(OR(J9="",N9="",M9=""),"",IF(N9<=T9,"안정",IF(N9<=S9,"적정",IF(N9<=R9,"소신","상향")))) -> 상향 | R9: {=IFERROR(IF(OR(J9="",M9="",F9=""),"",IF(F9="학생부종합",INDEX(종합배치표!$C:$Q,MATCH(J9,종합배치표!$B:$B,0),(MATCH(M9,{"A","B","C","D","E"},0)-1)*3+1),INDEX(교과배치표!$C:$Q,MATCH(J9,교과배치표!$B:$B,0),(MATCH(M9,{"A","B","C","D","E"},0)-1)*3+1))),"")} -> 2.95 | S9: {=IFERROR(IF(OR(J9="",M9="",F9=""),"",IF(F9="학생부종합",INDEX(종합배치표!$C:$Q,MATCH(J9,종합배치표!$B:$B,0),(MATCH(M9,{"A","B","C","D","E"},0)-1)*3+2),INDEX(교과배치표!$C:$Q,MATCH(J9,교과배치표!$B:$B,0),(MATCH(M9,{"A","B","C","D","E"},0)-1)*3+2))),"")} -> 2.55 | T9: {=IFERROR(IF(OR(J9="",M9="",F9=""),"",IF(F9="학생부종합",INDEX(종합배치표!$C:$Q,MATCH(J9,종합배치표!$B:$B,0),(MATCH(M9,{"A","B","C","D","E"},0)-1)*3+3),INDEX(교과배치표!$C:$Q,MATCH(J9,교과배치표!$B:$B,0),(MATCH(M9,{"A","B","C","D","E"},0)-1)*3+3))),"")} -> 2.25 | V9: =$W$2 -> 2.7 | W9: =IF(OR(J9="",V9="",M9=""),"",IF(V9<=T9,"안정",IF(V9<=S9,"적정",IF(V9<=R9,"소신","상향")))) -> 소신
B10: 1175 | C10: 서울 | D10: 서울 | E10: 고려대학교 | F10: 학생부종합 | G10: 계열적합전형 | H10: 통계학과 | I10: 인문 | J10: 고려계열인문1 | K10: 11 | M10: =IF(I10="","",IF(I10="인문",성적입력!$C$8,성적입력!$C$9)) -> A | N10: =성적입력!$C$15 -> 3 | P10: =IF(OR(J10="",N10="",M10=""),"",IF(N10<=T10,"안정",IF(N10<=S10,"적정",IF(N10<=R10,"소신","상향")))) -> 상향 | R10: {=IFERROR(IF(OR(J10="",M10="",F10=""),"",IF(F10="학생부종합",INDEX(종합배치표!$C:$Q,MATCH(J10,종합배치표!$B:$B,0),(MATCH(M10,{"A","B","C","D","E"},0)-1)*3+1),INDEX(교과배치표!$C:$Q,MATCH(J10,교과배치표!$B:$B,0),(MATCH(M10,{"A","B","C","D","E"},0)-1)*3+1))),"")} -> 2.95 | S10: {=IFERROR(IF(OR(J10="",M10="",F10=""),"",IF(F10="학생부종합",INDEX(종합배치표!$C:$Q,MATCH(J10,종합배치표!$B:$B,0),(MATCH(M10,{"A","B","C","D","E"},0)-1)*3+2),INDEX(교과배치표!$C:$Q,MATCH(J10,교과배치표!$B:$B,0),(MATCH(M10,{"A","B","C","D","E"},0)-1)*3+2))),"")} -> 2.55 | T10: {=IFERROR(IF(OR(J10="",M10="",F10=""),"",IF(F10="학생부종합",INDEX(종합배치표!$C:$Q,MATCH(J10,종합배치표!$B:$B,0),(MATCH(M10,{"A","B","C","D","E"},0)-1)*3+3),INDEX(교과배치표!$C:$Q,MATCH(J10,교과배치표!$B:$B,0),(MATCH(M10,{"A","B","C","D","E"},0)-1)*3+3))),"")} -> 2.25 | V10: =$W$2 -> 2.7 | W10: =IF(OR(J10="",V10="",M10=""),"",IF(V10<=T10,"안정",IF(V10<=S10,"적정",IF(V10<=R10,"소신","상향")))) -> 소신
B11: 1041 | C11: 서울 | D11: 서울 | E11: 고려대학교 | F11: 학생부종합 | G11: 계열적합전형 | H11: 국제학부 | I11: 인문 | J11: 고려계열인문2 | K11: 10 | M11: =IF(I11="","",IF(I11="인문",성적입력!$C$8,성적입력!$C$9)) -> A | N11: =성적입력!$C$15 -> 3 | P11: =IF(OR(J11="",N11="",M11=""),"",IF(N11<=T11,"안정",IF(N11<=S11,"적정",IF(N11<=R11,"소신","상향")))) -> 소신 | R11: {=IFERROR(IF(OR(J11="",M11="",F11=""),"",IF(F11="학생부종합",INDEX(종합배치표!$C:$Q,MATCH(J11,종합배치표!$B:$B,0),(MATCH(M11,{"A","B","C","D","E"},0)-1)*3+1),INDEX(교과배치표!$C:$Q,MATCH(J11,교과배치표!$B:$B,0),(MATCH(M11,{"A","B","C","D","E"},0)-1)*3+1))),"")} -> 3.05 | S11: {=IFERROR(IF(OR(J11="",M11="",F11=""),"",IF(F11="학생부종합",INDEX(종합배치표!$C:$Q,MATCH(J11,종합배치표!$B:$B,0),(MATCH(M11,{"A","B","C","D","E"},0)-1)*3+2),INDEX(교과배치표!$C:$Q,MATCH(J11,교과배치표!$B:$B,0),(MATCH(M11,{"A","B","C","D","E"},0)-1)*3+2))),"")} -> 2.65 | T11: {=IFERROR(IF(OR(J11="",M11="",F11=""),"",IF(F11="학생부종합",INDEX(종합배치표!$C:$Q,MATCH(J11,종합배치표!$B:$B,0),(MATCH(M11,{"A","B","C","D","E"},0)-1)*3+3),INDEX(교과배치표!$C:$Q,MATCH(J11,교과배치표!$B:$B,0),(MATCH(M11,{"A","B","C","D","E"},0)-1)*3+3))),"")} -> 2.35 | V11: =$W$2 -> 2.7 | W11: =IF(OR(J11="",V11="",M11=""),"",IF(V11<=T11,"안정",IF(V11<=S11,"적정",IF(V11<=R11,"소신","상향")))) -> 소신
B12: 1071 | C12: 서울 | D12: 서울 | E12: 고려대학교 | F12: 학생부종합 | G12: 계열적합전형 | H12: 보건정책관리학부 | I12: 인문 | J12: 고려계열인문2 | K12: 9 | M12: =IF(I12="","",IF(I12="인문",성적입력!$C$8,성적입력!$C$9)) -> A | N12: =성적입력!$C$15 -> 3 | P12: =IF(OR(J12="",N12="",M12=""),"",IF(N12<=T12,"안정",IF(N12<=S12,"적정",IF(N12<=R12,"소신","상향")))) -> 소신 | R12: {=IFERROR(IF(OR(J12="",M12="",F12=""),"",IF(F12="학생부종합",INDEX(종합배치표!$C:$Q,MATCH(J12,종합배치표!$B:$B,0),(MATCH(M12,{"A","B","C","D","E"},0)-1)*3+1),INDEX(교과배치표!$C:$Q,MATCH(J12,교과배치표!$B:$B,0),(MATCH(M12,{"A","B","C","D","E"},0)-1)*3+1))),"")} -> 3.05 | S12: {=IFERROR(IF(OR(J12="",M12="",F12=""),"",IF(F12="학생부종합",INDEX(종합배치표!$C:$Q,MATCH(J12,종합배치표!$B:$B,0),(MATCH(M12,{"A","B","C","D","E"},0)-1)*3+2),INDEX(교과배치표!$C:$Q,MATCH(J12,교과배치표!$B:$B,0),(MATCH(M12,{"A","B","C","D","E"},0)-1)*3+2))),"")} -> 2.65 | T12: {=IFERROR(IF(OR(J12="",M12="",F12=""),"",IF(F12="학생부종합",INDEX(종합배치표!$C:$Q,MATCH(J12,종합배치표!$B:$B,0),(MATCH(M12,{"A","B","C","D","E"},0)-1)*3+3),INDEX(교과배치표!$C:$Q,MATCH(J12,교과배치표!$B:$B,0),(MATCH(M12,{"A","B","C","D","E"},0)-1)*3+3))),"")} -> 2.35 | V12: =$W$2 -> 2.7 | W12: =IF(OR(J12="",V12="",M12=""),"",IF(V12<=T12,"안정",IF(V12<=S12,"적정",IF(V12<=R12,"소신","상향")))) -> 소신
B13: 1084 | C13: 서울 | D13: 서울 | E13: 고려대학교 | F13: 학생부종합 | G13: 계열적합전형 | H13: 사회학과 | I13: 인문 | J13: 고려계열인문2 | K13: 9 | M13: =IF(I13="","",IF(I13="인문",성적입력!$C$8,성적입력!$C$9)) -> A | N13: =성적입력!$C$15 -> 3 | P13: =IF(OR(J13="",N13="",M13=""),"",IF(N13<=T13,"안정",IF(N13<=S13,"적정",IF(N13<=R13,"소신","상향")))) -> 소신 | R13: {=IFERROR(IF(OR(J13="",M13="",F13=""),"",IF(F13="학생부종합",INDEX(종합배치표!$C:$Q,MATCH(J13,종합배치표!$B:$B,0),(MATCH(M13,{"A","B","C","D","E"},0)-1)*3+1),INDEX(교과배치표!$C:$Q,MATCH(J13,교과배치표!$B:$B,0),(MATCH(M13,{"A","B","C","D","E"},0)-1)*3+1))),"")} -> 3.05 | S13: {=IFERROR(IF(OR(J13="",M13="",F13=""),"",IF(F13="학생부종합",INDEX(종합배치표!$C:$Q,MATCH(J13,종합배치표!$B:$B,0),(MATCH(M13,{"A","B","C","D","E"},0)-1)*3+2),INDEX(교과배치표!$C:$Q,MATCH(J13,교과배치표!$B:$B,0),(MATCH(M13,{"A","B","C","D","E"},0)-1)*3+2))),"")} -> 2.65 | T13: {=IFERROR(IF(OR(J13="",M13="",F13=""),"",IF(F13="학생부종합",INDEX(종합배치표!$C:$Q,MATCH(J13,종합배치표!$B:$B,0),(MATCH(M13,{"A","B","C","D","E"},0)-1)*3+3),INDEX(교과배치표!$C:$Q,MATCH(J13,교과배치표!$B:$B,0),(MATCH(M13,{"A","B","C","D","E"},0)-1)*3+3))),"")} -> 2.35 | V13: =$W$2 -> 2.7 | W13: =IF(OR(J13="",V13="",M13=""),"",IF(V13<=T13,"안정",IF(V13<=S13,"적정",IF(V13<=R13,"소신","상향")))) -> 소신
B14: 1122 | C14: 서울 | D14: 서울 | E14: 고려대학교 | F14: 학생부종합 | G14: 계열적합전형 | H14: 언어학과 | I14: 인문 | J14: 고려계열인문2 | K14: 3 | M14: =IF(I14="","",IF(I14="인문",성적입력!$C$8,성적입력!$C$9)) -> A | N14: =성적입력!$C$15 -> 3 | P14: =IF(OR(J14="",N14="",M14=""),"",IF(N14<=T14,"안정",IF(N14<=S14,"적정",IF(N14<=R14,"소신","상향")))) -> 소신 | R14: {=IFERROR(IF(OR(J14="",M14="",F14=""),"",IF(F14="학생부종합",INDEX(종합배치표!$C:$Q,MATCH(J14,종합배치표!$B:$B,0),(MATCH(M14,{"A","B","C","D","E"},0)-1)*3+1),INDEX(교과배치표!$C:$Q,MATCH(J14,교과배치표!$B:$B,0),(MATCH(M14,{"A","B","C","D","E"},0)-1)*3+1))),"")} -> 3.05 | S14: {=IFERROR(IF(OR(J14="",M14="",F14=""),"",IF(F14="학생부종합",INDEX(종합배치표!$C:$Q,MATCH(J14,종합배치표!$B:$B,0),(MATCH(M14,{"A","B","C","D","E"},0)-1)*3+2),INDEX(교과배치표!$C:$Q,MATCH(J14,교과배치표!$B:$B,0),(MATCH(M14,{"A","B","C","D","E"},0)-1)*3+2))),"")} -> 2.65 | T14: {=IFERROR(IF(OR(J14="",M14="",F14=""),"",IF(F14="학생부종합",INDEX(종합배치표!$C:$Q,MATCH(J14,종합배치표!$B:$B,0),(MATCH(M14,{"A","B","C","D","E"},0)-1)*3+3),INDEX(교과배치표!$C:$Q,MATCH(J14,교과배치표!$B:$B,0),(MATCH(M14,{"A","B","C","D","E"},0)-1)*3+3))),"")} -> 2.35 | V14: =$W$2 -> 2.7 | W14: =IF(OR(J14="",V14="",M14=""),"",IF(V14<=T14,"안정",IF(V14<=S14,"적정",IF(V14<=R14,"소신","상향")))) -> 소신
B15: 1155 | C15: 서울 | D15: 서울 | E15: 고려대학교 | F15: 학생부종합 | G15: 계열적합전형 | H15: 정치외교학과 | I15: 인문 | J15: 고려계열인문2 | K15: 9 | M15: =IF(I15="","",IF(I15="인문",성적입력!$C$8,성적입력!$C$9)) -> A | N15: =성적입력!$C$15 -> 3 | P15: =IF(OR(J15="",N15="",M15=""),"",IF(N15<=T15,"안정",IF(N15<=S15,"적정",IF(N15<=R15,"소신","상향")))) -> 소신 | R15: {=IFERROR(IF(OR(J15="",M15="",F15=""),"",IF(F15="학생부종합",INDEX(종합배치표!$C:$Q,MATCH(J15,종합배치표!$B:$B,0),(MATCH(M15,{"A","B","C","D","E"},0)-1)*3+1),INDEX(교과배치표!$C:$Q,MATCH(J15,교과배치표!$B:$B,0),(MATCH(M15,{"A","B","C","D","E"},0)-1)*3+1))),"")} -> 3.05 | S15: {=IFERROR(IF(OR(J15="",M15="",F15=""),"",IF(F15="학생부종합",INDEX(종합배치표!$C:$Q,MATCH(J15,종합배치표!$B:$B,0),(MATCH(M15,{"A","B","C","D","E"},0)-1)*3+2),INDEX(교과배치표!$C:$Q,MATCH(J15,교과배치표!$B:$B,0),(MATCH(M15,{"A","B","C","D","E"},0)-1)*3+2))),"")} -> 2.65 | T15: {=IFERROR(IF(OR(J15="",M15="",F15=""),"",IF(F15="학생부종합",INDEX(종합배치표!$C:$Q,MATCH(J15,종합배치표!$B:$B,0),(MATCH(M15,{"A","B","C","D","E"},0)-1)*3+3),INDEX(교과배치표!$C:$Q,MATCH(J15,교과배치표!$B:$B,0),(MATCH(M15,{"A","B","C","D","E"},0)-1)*3+3))),"")} -> 2.35 | V15: =$W$2 -> 2.7 | W15: =IF(OR(J15="",V15="",M15=""),"",IF(V15<=T15,"안정",IF(V15<=S15,"적정",IF(V15<=R15,"소신","상향")))) -> 소신
B16: 1185 | C16: 서울 | D16: 서울 | E16: 고려대학교 | F16: 학생부종합 | G16: 계열적합전형 | H16: 행정학과 | I16: 인문 | J16: 고려계열인문2 | K16: 9 | M16: =IF(I16="","",IF(I16="인문",성적입력!$C$8,성적입력!$C$9)) -> A | N16: =성적입력!$C$15 -> 3 | P16: =IF(OR(J16="",N16="",M16=""),"",IF(N16<=T16,"안정",IF(N16<=S16,"적정",IF(N16<=R16,"소신","상향")))) -> 소신 | R16: {=IFERROR(IF(OR(J16="",M16="",F16=""),"",IF(F16="학생부종합",INDEX(종합배치표!$C:$Q,MATCH(J16,종합배치표!$B:$B,0),(MATCH(M16,{"A","B","C","D","E"},0)-1)*3+1),INDEX(교과배치표!$C:$Q,MATCH(J16,교과배치표!$B:$B,0),(MATCH(M16,{"A","B","C","D","E"},0)-1)*3+1))),"")} -> 3.05 | S16: {=IFERROR(IF(OR(J16="",M16="",F16=""),"",IF(F16="학생부종합",INDEX(종합배치표!$C:$Q,MATCH(J16,종합배치표!$B:$B,0),(MATCH(M16,{"A","B","C","D","E"},0)-1)*3+2),INDEX(교과배치표!$C:$Q,MATCH(J16,교과배치표!$B:$B,0),(MATCH(M16,{"A","B","C","D","E"},0)-1)*3+2))),"")} -> 2.65 | T16: {=IFERROR(IF(OR(J16="",M16="",F16=""),"",IF(F16="학생부종합",INDEX(종합배치표!$C:$Q,MATCH(J16,종합배치표!$B:$B,0),(MATCH(M16,{"A","B","C","D","E"},0)-1)*3+3),INDEX(교과배치표!$C:$Q,MATCH(J16,교과배치표!$B:$B,0),(MATCH(M16,{"A","B","C","D","E"},0)-1)*3+3))),"")} -> 2.35 | V16: =$W$2 -> 2.7 | W16: =IF(OR(J16="",V16="",M16=""),"",IF(V16<=T16,"안정",IF(V16<=S16,"적정",IF(V16<=R16,"소신","상향")))) -> 소신
... B583: 3618 | C583: 서울 | D583: 서울 | E583: 연세대학교 | F583: 학생부교과 | G583: 추천형전형 | H583: 진리자유학부(자연) | I583: 자연 | J583: 연세교과자전자연 | K583: 21 | M583: =IF(I583="","",IF(I583="인문",성적입력!$C$8,성적입력!$C$9)) -> A | N583: =성적입력!$C$15 -> 3 | P583: =IF(OR(J583="",N583="",M583=""),"",IF(N583<=T583,"안정",IF(N583<=S583,"적정",IF(N583<=R583,"소신","상향")))) -> 상향 | R583: {=IFERROR(IF(OR(J583="",M583="",F583=""),"",IF(F583="학생부종합",INDEX(종합배치표!$C:$Q,MATCH(J583,종합배치표!$B:$B,0),(MATCH(M583,{"A","B","C","D","E"},0)-1)*3+1),INDEX(교과배치표!$C:$Q,MATCH(J583,교과배치표!$B:$B,0),(MATCH(M583,{"A","B","C","D","E"},0)-1)*3+1))),"")} -> 0 | S583: {=IFERROR(IF(OR(J583="",M583="",F583=""),"",IF(F583="학생부종합",INDEX(종합배치표!$C:$Q,MATCH(J583,종합배치표!$B:$B,0),(MATCH(M583,{"A","B","C","D","E"},0)-1)*3+2),INDEX(교과배치표!$C:$Q,MATCH(J583,교과배치표!$B:$B,0),(MATCH(M583,{"A","B","C","D","E"},0)-1)*3+2))),"")} -> 0 | T583: {=IFERROR(IF(OR(J583="",M583="",F583=""),"",IF(F583="학생부종합",INDEX(종합배치표!$C:$Q,MATCH(J583,종합배치표!$B:$B,0),(MATCH(M583,{"A","B","C","D","E"},0)-1)*3+3),INDEX(교과배치표!$C:$Q,MATCH(J583,교과배치표!$B:$B,0),(MATCH(M583,{"A","B","C","D","E"},0)-1)*3+3))),"")} -> 0 | V583: =$W$2 -> 2.7 | W583: =IF(OR(J583="",V583="",M583=""),"",IF(V583<=T583,"안정",IF(V583<=S583,"적정",IF(V583<=R583,"소신","상향")))) -> 상향
B584: 3595 | C584: 인천 | D584: 인천 | E584: 연세대학교 | F584: 학생부종합 | G584: 국제형전형 | H584: 융합인문사회과학부(HASS) | I584: 인문 | J584: 연세국제인문2 | K584: 국내:100 해외:30 | M584: =IF(I584="","",IF(I584="인문",성적입력!$C$8,성적입력!$C$9)) -> A | N584: =성적입력!$C$15 -> 3 | P584: =IF(OR(J584="",N584="",M584=""),"",IF(N584<=T584,"안정",IF(N584<=S584,"적정",IF(N584<=R584,"소신","상향")))) -> 적정 | R584: {=IFERROR(IF(OR(J584="",M584="",F584=""),"",IF(F584="학생부종합",INDEX(종합배치표!$C:$Q,MATCH(J584,종합배치표!$B:$B,0),(MATCH(M584,{"A","B","C","D","E"},0)-1)*3+1),INDEX(교과배치표!$C:$Q,MATCH(J584,교과배치표!$B:$B,0),(MATCH(M584,{"A","B","C","D","E"},0)-1)*3+1))),"")} -> 3.4 | S584: {=IFERROR(IF(OR(J584="",M584="",F584=""),"",IF(F584="학생부종합",INDEX(종합배치표!$C:$Q,MATCH(J584,종합배치표!$B:$B,0),(MATCH(M584,{"A","B","C","D","E"},0)-1)*3+2),INDEX(교과배치표!$C:$Q,MATCH(J584,교과배치표!$B:$B,0),(MATCH(M584,{"A","B","C","D","E"},0)-1)*3+2))),"")} -> 3 | T584: {=IFERROR(IF(OR(J584="",M584="",F584=""),"",IF(F584="학생부종합",INDEX(종합배치표!$C:$Q,MATCH(J584,종합배치표!$B:$B,0),(MATCH(M584,{"A","B","C","D","E"},0)-1)*3+3),INDEX(교과배치표!$C:$Q,MATCH(J584,교과배치표!$B:$B,0),(MATCH(M584,{"A","B","C","D","E"},0)-1)*3+3))),"")} -> 2.7 | V584: =$W$2 -> 2.7 | W584: =IF(OR(J584="",V584="",M584=""),"",IF(V584<=T584,"안정",IF(V584<=S584,"적정",IF(V584<=R584,"소신","상향")))) -> 안정
B585: 3524 | C585: 서울 | D585: 서울 | E585: 연세대학교 | F585: 학생부종합 | G585: 국제형전형 | H585: 글로벌인재학부 | I585: 인문 | J585: 연세국제인문3 | K585: 10 | M585: =IF(I585="","",IF(I585="인문",성적입력!$C$8,성적입력!$C$9)) -> A | N585: =성적입력!$C$15 -> 3 | P585: =IF(OR(J585="",N585="",M585=""),"",IF(N585<=T585,"안정",IF(N585<=S585,"적정",IF(N585<=R585,"소신","상향")))) -> 적정 | R585: {=IFERROR(IF(OR(J585="",M585="",F585=""),"",IF(F585="학생부종합",INDEX(종합배치표!$C:$Q,MATCH(J585,종합배치표!$B:$B,0),(MATCH(M585,{"A","B","C","D","E"},0)-1)*3+1),INDEX(교과배치표!$C:$Q,MATCH(J585,교과배치표!$B:$B,0),(MATCH(M585,{"A","B","C","D","E"},0)-1)*3+1))),"")} -> 3.5 | S585: {=IFERROR(IF(OR(J585="",M585="",F585=""),"",IF(F585="학생부종합",INDEX(종합배치표!$C:$Q,MATCH(J585,종합배치표!$B:$B,0),(MATCH(M585,{"A","B","C","D","E"},0)-1)*3+2),INDEX(교과배치표!$C:$Q,MATCH(J585,교과배치표!$B:$B,0),(MATCH(M585,{"A","B","C","D","E"},0)-1)*3+2))),"")} -> 3.1 | T585: {=IFERROR(IF(OR(J585="",M585="",F585=""),"",IF(F585="학생부종합",INDEX(종합배치표!$C:$Q,MATCH(J585,종합배치표!$B:$B,0),(MATCH(M585,{"A","B","C","D","E"},0)-1)*3+3),INDEX(교과배치표!$C:$Q,MATCH(J585,교과배치표!$B:$B,0),(MATCH(M585,{"A","B","C","D","E"},0)-1)*3+3))),"")} -> 2.8 | V585: =$W$2 -> 2.7 | W585: =IF(OR(J585="",V585="",M585=""),"",IF(V585<=T585,"안정",IF(V585<=S585,"적정",IF(V585<=R585,"소신","상향")))) -> 안정
B586: 3581 | C586: 서울 | D586: 서울 | E586: 연세대학교 | F586: 학생부종합 | G586: 국제형전형 | H586: 아시아학전공 | I586: 인문 | J586: 연세국제인문3 | K586: 20 | M586: =IF(I586="","",IF(I586="인문",성적입력!$C$8,성적입력!$C$9)) -> A | N586: =성적입력!$C$15 -> 3 | P586: =IF(OR(J586="",N586="",M586=""),"",IF(N586<=T586,"안정",IF(N586<=S586,"적정",IF(N586<=R586,"소신","상향")))) -> 적정 | R586: {=IFERROR(IF(OR(J586="",M586="",F586=""),"",IF(F586="학생부종합",INDEX(종합배치표!$C:$Q,MATCH(J586,종합배치표!$B:$B,0),(MATCH(M586,{"A","B","C","D","E"},0)-1)*3+1),INDEX(교과배치표!$C:$Q,MATCH(J586,교과배치표!$B:$B,0),(MATCH(M586,{"A","B","C","D","E"},0)-1)*3+1))),"")} -> 3.5 | S586: {=IFERROR(IF(OR(J586="",M586="",F586=""),"",IF(F586="학생부종합",INDEX(종합배치표!$C:$Q,MATCH(J586,종합배치표!$B:$B,0),(MATCH(M586,{"A","B","C","D","E"},0)-1)*3+2),INDEX(교과배치표!$C:$Q,MATCH(J586,교과배치표!$B:$B,0),(MATCH(M586,{"A","B","C","D","E"},0)-1)*3+2))),"")} -> 3.1 | T586: {=IFERROR(IF(OR(J586="",M586="",F586=""),"",IF(F586="학생부종합",INDEX(종합배치표!$C:$Q,MATCH(J586,종합배치표!$B:$B,0),(MATCH(M586,{"A","B","C","D","E"},0)-1)*3+3),INDEX(교과배치표!$C:$Q,MATCH(J586,교과배치표!$B:$B,0),(MATCH(M586,{"A","B","C","D","E"},0)-1)*3+3))),"")} -> 2.8 | V586: =$W$2 -> 2.7 | W586: =IF(OR(J586="",V586="",M586=""),"",IF(V586<=T586,"안정",IF(V586<=S586,"적정",IF(V586<=R586,"소신","상향")))) -> 안정
B587: 3588 | C587: 서울 | D587: 서울 | E587: 연세대학교 | F587: 학생부종합 | G587: 국제형전형 | H587: 언더우드학부(인문사회) | I587: 인문 | J587: 연세국제인문3 | K587: 30 | M587: =IF(I587="","",IF(I587="인문",성적입력!$C$8,성적입력!$C$9)) -> A | N587: =성적입력!$C$15 -> 3 | P587: =IF(OR(J587="",N587="",M587=""),"",IF(N587<=T587,"안정",IF(N587<=S587,"적정",IF(N587<=R587,"소신","상향")))) -> 적정 | R587: {=IFERROR(IF(OR(J587="",M587="",F587=""),"",IF(F587="학생부종합",INDEX(종합배치표!$C:$Q,MATCH(J587,종합배치표!$B:$B,0),(MATCH(M587,{"A","B","C","D","E"},0)-1)*3+1),INDEX(교과배치표!$C:$Q,MATCH(J587,교과배치표!$B:$B,0),(MATCH(M587,{"A","B","C","D","E"},0)-1)*3+1))),"")} -> 3.5 | S587: {=IFERROR(IF(OR(J587="",M587="",F587=""),"",IF(F587="학생부종합",INDEX(종합배치표!$C:$Q,MATCH(J587,종합배치표!$B:$B,0),(MATCH(M587,{"A","B","C","D","E"},0)-1)*3+2),INDEX(교과배치표!$C:$Q,MATCH(J587,교과배치표!$B:$B,0),(MATCH(M587,{"A","B","C","D","E"},0)-1)*3+2))),"")} -> 3.1 | T587: {=IFERROR(IF(OR(J587="",M587="",F587=""),"",IF(F587="학생부종합",INDEX(종합배치표!$C:$Q,MATCH(J587,종합배치표!$B:$B,0),(MATCH(M587,{"A","B","C","D","E"},0)-1)*3+3),INDEX(교과배치표!$C:$Q,MATCH(J587,교과배치표!$B:$B,0),(MATCH(M587,{"A","B","C","D","E"},0)-1)*3+3))),"")} -> 2.8 | V587: =$W$2 -> 2.7 | W587: =IF(OR(J587="",V587="",M587=""),"",IF(V587<=T587,"안정",IF(V587<=S587,"적정",IF(V587<=R587,"소신","상향")))) -> 안정
B588: 3586 | C588: 서울 | D588: 서울 | E588: 연세대학교 | F588: 학생부종합 | G588: 국제형전형 | H588: 언더우드학부(생명과학공학) | I588: 자연 | J588: 연세국제자연3 | K588: 5 | M588: =IF(I588="","",IF(I588="인문",성적입력!$C$8,성적입력!$C$9)) -> A | N588: =성적입력!$C$15 -> 3 | P588: =IF(OR(J588="",N588="",M588=""),"",IF(N588<=T588,"안정",IF(N588<=S588,"적정",IF(N588<=R588,"소신","상향")))) -> 안정 | R588: {=IFERROR(IF(OR(J588="",M588="",F588=""),"",IF(F588="학생부종합",INDEX(종합배치표!$C:$Q,MATCH(J588,종합배치표!$B:$B,0),(MATCH(M588,{"A","B","C","D","E"},0)-1)*3+1),INDEX(교과배치표!$C:$Q,MATCH(J588,교과배치표!$B:$B,0),(MATCH(M588,{"A","B","C","D","E"},0)-1)*3+1))),"")} -> 3.75 | S588: {=IFERROR(IF(OR(J588="",M588="",F588=""),"",IF(F588="학생부종합",INDEX(종합배치표!$C:$Q,MATCH(J588,종합배치표!$B:$B,0),(MATCH(M588,{"A","B","C","D","E"},0)-1)*3+2),INDEX(교과배치표!$C:$Q,MATCH(J588,교과배치표!$B:$B,0),(MATCH(M588,{"A","B","C","D","E"},0)-1)*3+2))),"")} -> 3.35 | T588: {=IFERROR(IF(OR(J588="",M588="",F588=""),"",IF(F588="학생부종합",INDEX(종합배치표!$C:$Q,MATCH(J588,종합배치표!$B:$B,0),(MATCH(M588,{"A","B","C","D","E"},0)-1)*3+3),INDEX(교과배치표!$C:$Q,MATCH(J588,교과배치표!$B:$B,0),(MATCH(M588,{"A","B","C","D","E"},0)-1)*3+3))),"")} -> 3.05 | V588: =$W$2 -> 2.7 | W588: =IF(OR(J588="",V588="",M588=""),"",IF(V588<=T588,"안정",IF(V588<=S588,"적정",IF(V588<=R588,"소신","상향")))) -> 안정
B589: 3594 | C589: 인천 | D589: 인천 | E589: 연세대학교 | F589: 학생부종합 | G589: 국제형전형 | H589: 융합과학공학부(ISE) | I589: 자연 | J589: 연세국제자연3 | K589: 국내:40 해외:20 | M589: =IF(I589="","",IF(I589="인문",성적입력!$C$8,성적입력!$C$9)) -> A | N589: =성적입력!$C$15 -> 3 | P589: =IF(OR(J589="",N589="",M589=""),"",IF(N589<=T589,"안정",IF(N589<=S589,"적정",IF(N589<=R589,"소신","상향")))) -> 안정 | R589: {=IFERROR(IF(OR(J589="",M589="",F589=""),"",IF(F589="학생부종합",INDEX(종합배치표!$C:$Q,MATCH(J589,종합배치표!$B:$B,0),(MATCH(M589,{"A","B","C","D","E"},0)-1)*3+1),INDEX(교과배치표!$C:$Q,MATCH(J589,교과배치표!$B:$B,0),(MATCH(M589,{"A","B","C","D","E"},0)-1)*3+1))),"")} -> 3.75 | S589: {=IFERROR(IF(OR(J589="",M589="",F589=""),"",IF(F589="학생부종합",INDEX(종합배치표!$C:$Q,MATCH(J589,종합배치표!$B:$B,0),(MATCH(M589,{"A","B","C","D","E"},0)-1)*3+2),INDEX(교과배치표!$C:$Q,MATCH(J589,교과배치표!$B:$B,0),(MATCH(M589,{"A","B","C","D","E"},0)-1)*3+2))),"")} -> 3.35 | T589: {=IFERROR(IF(OR(J589="",M589="",F589=""),"",IF(F589="학생부종합",INDEX(종합배치표!$C:$Q,MATCH(J589,종합배치표!$B:$B,0),(MATCH(M589,{"A","B","C","D","E"},0)-1)*3+3),INDEX(교과배치표!$C:$Q,MATCH(J589,교과배치표!$B:$B,0),(MATCH(M589,{"A","B","C","D","E"},0)-1)*3+3))),"")} -> 3.05 | V589: =$W$2 -> 2.7 | W589: =IF(OR(J589="",V589="",M589=""),"",IF(V589<=T589,"안정",IF(V589<=S589,"적정",IF(V589<=R589,"소신","상향")))) -> 안정
B590: 3517 | C590: 서울 | D590: 서울 | E590: 연세대학교 | F590: 학생부종합 | G590: 활동우수형전형 | H590: 경영학과 | I590: 인문 | J590: 연세활동인문1 | K590: 38 | M590: =IF(I590="","",IF(I590="인문",성적입력!$C$8,성적입력!$C$9)) -> A | N590: =성적입력!$C$15 -> 3 | P590: =IF(OR(J590="",N590="",M590=""),"",IF(N590<=T590,"안정",IF(N590<=S590,"적정",IF(N590<=R590,"소신","상향")))) -> 상향 | R590: {=IFERROR(IF(OR(J590="",M590="",F590=""),"",IF(F590="학생부종합",INDEX(종합배치표!$C:$Q,MATCH(J590,종합배치표!$B:$B,0),(MATCH(M590,{"A","B","C","D","E"},0)-1)*3+1),INDEX(교과배치표!$C:$Q,MATCH(J590,교과배치표!$B:$B,0),(MATCH(M590,{"A","B","C","D","E"},0)-1)*3+1))),"")} -> 2.6 | S590: {=IFERROR(IF(OR(J590="",M590="",F590=""),"",IF(F590="학생부종합",INDEX(종합배치표!$C:$Q,MATCH(J590,종합배치표!$B:$B,0),(MATCH(M590,{"A","B","C","D","E"},0)-1)*3+2),INDEX(교과배치표!$C:$Q,MATCH(J590,교과배치표!$B:$B,0),(MATCH(M590,{"A","B","C","D","E"},0)-1)*3+2))),"")} -> 2.2 | T590: {=IFERROR(IF(OR(J590="",M590="",F590=""),"",IF(F590="학생부종합",INDEX(종합배치표!$C:$Q,MATCH(J590,종합배치표!$B:$B,0),(MATCH(M590,{"A","B","C","D","E"},0)-1)*3+3),INDEX(교과배치표!$C:$Q,MATCH(J590,교과배치표!$B:$B,0),(MATCH(M590,{"A","B","C","D","E"},0)-1)*3+3))),"")} -> 1.9 | V590: =$W$2 -> 2.7 | W590: =IF(OR(J590="",V590="",M590=""),"",IF(V590<=T590,"안정",IF(V590<=S590,"적정",IF(V590<=R590,"소신","상향")))) -> 상향
B591: 3519 | C591: 서울 | D591: 서울 | E591: 연세대학교 | F591: 학생부종합 | G591: 활동우수형전형 | H591: 경제학부 | I591: 인문 | J591: 연세활동인문1 | K591: 32 | M591: =IF(I591="","",IF(I591="인문",성적입력!$C$8,성적입력!$C$9)) -> A | N591: =성적입력!$C$15 -> 3 | P591: =IF(OR(J591="",N591="",M591=""),"",IF(N591<=T591,"안정",IF(N591<=S591,"적정",IF(N591<=R591,"소신","상향")))) -> 상향 | R591: {=IFERROR(IF(OR(J591="",M591="",F591=""),"",IF(F591="학생부종합",INDEX(종합배치표!$C:$Q,MATCH(J591,종합배치표!$B:$B,0),(MATCH(M591,{"A","B","C","D","E"},0)-1)*3+1),INDEX(교과배치표!$C:$Q,MATCH(J591,교과배치표!$B:$B,0),(MATCH(M591,{"A","B","C","D","E"},0)-1)*3+1))),"")} -> 2.6 | S591: {=IFERROR(IF(OR(J591="",M591="",F591=""),"",IF(F591="학생부종합",INDEX(종합배치표!$C:$Q,MATCH(J591,종합배치표!$B:$B,0),(MATCH(M591,{"A","B","C","D","E"},0)-1)*3+2),INDEX(교과배치표!$C:$Q,MATCH(J591,교과배치표!$B:$B,0),(MATCH(M591,{"A","B","C","D","E"},0)-1)*3+2))),"")} -> 2.2 | T591: {=IFERROR(IF(OR(J591="",M591="",F591=""),"",IF(F591="학생부종합",INDEX(종합배치표!$C:$Q,MATCH(J591,종합배치표!$B:$B,0),(MATCH(M591,{"A","B","C","D","E"},0)-1)*3+3),INDEX(교과배치표!$C:$Q,MATCH(J591,교과배치표!$B:$B,0),(MATCH(M591,{"A","B","C","D","E"},0)-1)*3+3))),"")} -> 1.9 | V591: =$W$2 -> 2.7 | W591: =IF(OR(J591="",V591="",M591=""),"",IF(V591<=T591,"안정",IF(V591<=S591,"적정",IF(V591<=R591,"소신","상향")))) -> 상향
B592: 3578 | C592: 서울 | D592: 서울 | E592: 연세대학교 | F592: 학생부종합 | G592: 활동우수형전형 | H592: 심리학과 | I592: 인문 | J592: 연세활동인문1 | K592: 8 | M592: =IF(I592="","",IF(I592="인문",성적입력!$C$8,성적입력!$C$9)) -> A | N592: =성적입력!$C$15 -> 3 | P592: =IF(OR(J592="",N592="",M592=""),"",IF(N592<=T592,"안정",IF(N592<=S592,"적정",IF(N592<=R592,"소신","상향")))) -> 상향 | R592: {=IFERROR(IF(OR(J592="",M592="",F592=""),"",IF(F592="학생부종합",INDEX(종합배치표!$C:$Q,MATCH(J592,종합배치표!$B:$B,0),(MATCH(M592,{"A","B","C","D","E"},0)-1)*3+1),INDEX(교과배치표!$C:$Q,MATCH(J592,교과배치표!$B:$B,0),(MATCH(M592,{"A","B","C","D","E"},0)-1)*3+1))),"")} -> 2.6 | S592: {=IFERROR(IF(OR(J592="",M592="",F592=""),"",IF(F592="학생부종합",INDEX(종합배치표!$C:$Q,MATCH(J592,종합배치표!$B:$B,0),(MATCH(M592,{"A","B","C","D","E"},0)-1)*3+2),INDEX(교과배치표!$C:$Q,MATCH(J592,교과배치표!$B:$B,0),(MATCH(M592,{"A","B","C","D","E"},0)-1)*3+2))),"")} -> 2.2 | T592: {=IFERROR(IF(OR(J592="",M592="",F592=""),"",IF(F592="학생부종합",INDEX(종합배치표!$C:$Q,MATCH(J592,종합배치표!$B:$B,0),(MATCH(M592,{"A","B","C","D","E"},0)-1)*3+3),INDEX(교과배치표!$C:$Q,MATCH(J592,교과배치표!$B:$B,0),(MATCH(M592,{"A","B","C","D","E"},0)-1)*3+3))),"")} -> 1.9 | V592: =$W$2 -> 2.7 | W592: =IF(OR(J592="",V592="",M592=""),"",IF(V592<=T592,"안정",IF(V592<=S592,"적정",IF(V592<=R592,"소신","상향")))) -> 상향
B593: 3591 | C593: 서울 | D593: 서울 | E593: 연세대학교 | F593: 학생부종합 | G593: 활동우수형전형 | H593: 언론홍보영상학부 | I593: 인문 | J593: 연세활동인문1 | K593: 8 | M593: =IF(I593="","",IF(I593="인문",성적입력!$C$8,성적입력!$C$9)) -> A | N593: =성적입력!$C$15 -> 3 | P593: =IF(OR(J593="",N593="",M593=""),"",IF(N593<=T593,"안정",IF(N593<=S593,"적정",IF(N593<=R593,"소신","상향")))) -> 상향 | R593: {=IFERROR(IF(OR(J593="",M593="",F593=""),"",IF(F593="학생부종합",INDEX(종합배치표!$C:$Q,MATCH(J593,종합배치표!$B:$B,0),(MATCH(M593,{"A","B","C","D","E"},0)-1)*3+1),INDEX(교과배치표!$C:$Q,MATCH(J593,교과배치표!$B:$B,0),(MATCH(M593,{"A","B","C","D","E"},0)-1)*3+1))),"")} -> 2.6 | S593: {=IFERROR(IF(OR(J593="",M593="",F593=""),"",IF(F593="학생부종합",INDEX(종합배치표!$C:$Q,MATCH(J593,종합배치표!$B:$B,0),(MATCH(M593,{"A","B","C","D","E"},0)-1)*3+2),INDEX(교과배치표!$C:$Q,MATCH(J593,교과배치표!$B:$B,0),(MATCH(M593,{"A","B","C","D","E"},0)-1)*3+2))),"")} -> 2.2 | T593: {=IFERROR(IF(OR(J593="",M593="",F593=""),"",IF(F593="학생부종합",INDEX(종합배치표!$C:$Q,MATCH(J593,종합배치표!$B:$B,0),(MATCH(M593,{"A","B","C","D","E"},0)-1)*3+3),INDEX(교과배치표!$C:$Q,MATCH(J593,교과배치표!$B:$B,0),(MATCH(M593,{"A","B","C","D","E"},0)-1)*3+3))),"")} -> 1.9 | V593: =$W$2 -> 2.7 | W593: =IF(OR(J593="",V593="",M593=""),"",IF(V593<=T593,"안정",IF(V593<=S593,"적정",IF(V593<=R593,"소신","상향")))) -> 상향
B594: 3597 | C594: 서울 | D594: 서울 | E594: 연세대학교 | F594: 학생부종합 | G594: 활동우수형전형 | H594: 응용통계학과 | I594: 인문 | J594: 연세활동인문1 | K594: 11 | M594: =IF(I594="","",IF(I594="인문",성적입력!$C$8,성적입력!$C$9)) -> A | N594: =성적입력!$C$15 -> 3 | P594: =IF(OR(J594="",N594="",M594=""),"",IF(N594<=T594,"안정",IF(N594<=S594,"적정",IF(N594<=R594,"소신","상향")))) -> 상향 | R594: {=IFERROR(IF(OR(J594="",M594="",F594=""),"",IF(F594="학생부종합",INDEX(종합배치표!$C:$Q,MATCH(J594,종합배치표!$B:$B,0),(MATCH(M594,{"A","B","C","D","E"},0)-1)*3+1),INDEX(교과배치표!$C:$Q,MATCH(J594,교과배치표!$B:$B,0),(MATCH(M594,{"A","B","C","D","E"},0)-1)*3+1))),"")} -> 2.6 | S594: {=IFERROR(IF(OR(J594="",M594="",F594=""),"",IF(F594="학생부종합",INDEX(종합배치표!$C:$Q,MATCH(J594,종합배치표!$B:$B,0),(MATCH(M594,{"A","B","C","D","E"},0)-1)*3+2),INDEX(교과배치표!$C:$Q,MATCH(J594,교과배치표!$B:$B,0),(MATCH(M594,{"A","B","C","D","E"},0)-1)*3+2))),"")} -> 2.2 | T594: {=IFERROR(IF(OR(J594="",M594="",F594=""),"",IF(F594="학생부종합",INDEX(종합배치표!$C:$Q,MATCH(J594,종합배치표!$B:$B,0),(MATCH(M594,{"A","B","C","D","E"},0)-1)*3+3),INDEX(교과배치표!$C:$Q,MATCH(J594,교과배치표!$B:$B,0),(MATCH(M594,{"A","B","C","D","E"},0)-1)*3+3))),"")} -> 1.9 | V594: =$W$2 -> 2.7 | W594: =IF(OR(J594="",V594="",M594=""),"",IF(V594<=T594,"안정",IF(V594<=S594,"적정",IF(V594<=R594,"소신","상향")))) -> 상향
B595: 3521 | C595: 서울 | D595: 서울 | E595: 연세대학교 | F595: 학생부종합 | G595: 활동우수형전형 | H595: 교육학부 | I595: 인문 | J595: 연세활동인문2 | K595: 12 | M595: =IF(I595="","",IF(I595="인문",성적입력!$C$8,성적입력!$C$9)) -> A | N595: =성적입력!$C$15 -> 3 | P595: =IF(OR(J595="",N595="",M595=""),"",IF(N595<=T595,"안정",IF(N595<=S595,"적정",IF(N595<=R595,"소신","상향")))) -> 상향 | R595: {=IFERROR(IF(OR(J595="",M595="",F595=""),"",IF(F595="학생부종합",INDEX(종합배치표!$C:$Q,MATCH(J595,종합배치표!$B:$B,0),(MATCH(M595,{"A","B","C","D","E"},0)-1)*3+1),INDEX(교과배치표!$C:$Q,MATCH(J595,교과배치표!$B:$B,0),(MATCH(M595,{"A","B","C","D","E"},0)-1)*3+1))),"")} -> 2.7 | S595: {=IFERROR(IF(OR(J595="",M595="",F595=""),"",IF(F595="학생부종합",INDEX(종합배치표!$C:$Q,MATCH(J595,종합배치표!$B:$B,0),(MATCH(M595,{"A","B","C","D","E"},0)-1)*3+2),INDEX(교과배치표!$C:$Q,MATCH(J595,교과배치표!$B:$B,0),(MATCH(M595,{"A","B","C","D","E"},0)-1)*3+2))),"")} -> 2.3 | T595: {=IFERROR(IF(OR(J595="",M595="",F595=""),"",IF(F595="학생부종합",INDEX(종합배치표!$C:$Q,MATCH(J595,종합배치표!$B:$B,0),(MATCH(M595,{"A","B","C","D","E"},0)-1)*3+3),INDEX(교과배치표!$C:$Q,MATCH(J595,교과배치표!$B:$B,0),(MATCH(M595,{"A","B","C","D","E"},0)-1)*3+3))),"")} -> 2 | V595: =$W$2 -> 2.7 | W595: =IF(OR(J595="",V595="",M595=""),"",IF(V595<=T595,"안정",IF(V595<=S595,"적정",IF(V595<=R595,"소신","상향")))) -> 소신
B596: 3552 | C596: 서울 | D596: 서울 | E596: 연세대학교 | F596: 학생부종합 | G596: 활동우수형전형 | H596: 사회학과 | I596: 인문 | J596: 연세활동인문2 | K596: 8 | M596: =IF(I596="","",IF(I596="인문",성적입력!$C$8,성적입력!$C$9)) -> A | N596: =성적입력!$C$15 -> 3 | P596: =IF(OR(J596="",N596="",M596=""),"",IF(N596<=T596,"안정",IF(N596<=S596,"적정",IF(N596<=R596,"소신","상향")))) -> 상향 | R596: {=IFERROR(IF(OR(J596="",M596="",F596=""),"",IF(F596="학생부종합",INDEX(종합배치표!$C:$Q,MATCH(J596,종합배치표!$B:$B,0),(MATCH(M596,{"A","B","C","D","E"},0)-1)*3+1),INDEX(교과배치표!$C:$Q,MATCH(J596,교과배치표!$B:$B,0),(MATCH(M596,{"A","B","C","D","E"},0)-1)*3+1))),"")} -> 2.7 | S596: {=IFERROR(IF(OR(J596="",M596="",F596=""),"",IF(F596="학생부종합",INDEX(종합배치표!$C:$Q,MATCH(J596,종합배치표!$B:$B,0),(MATCH(M596,{"A","B","C","D","E"},0)-1)*3+2),INDEX(교과배치표!$C:$Q,MATCH(J596,교과배치표!$B:$B,0),(MATCH(M596,{"A","B","C","D","E"},0)-1)*3+2))),"")} -> 2.3 | T596: {=IFERROR(IF(OR(J596="",M596="",F596=""),"",IF(F596="학생부종합",INDEX(종합배치표!$C:$Q,MATCH(J596,종합배치표!$B:$B,0),(MATCH(M596,{"A","B","C","D","E"},0)-1)*3+3),INDEX(교과배치표!$C:$Q,MATCH(J596,교과배치표!$B:$B,0),(MATCH(M596,{"A","B","C","D","E"},0)-1)*3+3))),"")} -> 2 | V596: =$W$2 -> 2.7 | W596: =IF(OR(J596="",V596="",M596=""),"",IF(V596<=T596,"안정",IF(V596<=S596,"적정",IF(V596<=R596,"소신","상향")))) -> 소신
B597: 3608 | C597: 서울 | D597: 서울 | E597: 연세대학교 | F597: 학생부종합 | G597: 활동우수형전형 | H597: 정치외교학과 | I597: 인문 | J597: 연세활동인문2 | K597: 16 | M597: =IF(I597="","",IF(I597="인문",성적입력!$C$8,성적입력!$C$9)) -> A | N597: =성적입력!$C$15 -> 3 | P597: =IF(OR(J597="",N597="",M597=""),"",IF(N597<=T597,"안정",IF(N597<=S597,"적정",IF(N597<=R597,"소신","상향")))) -> 상향 | R597: {=IFERROR(IF(OR(J597="",M597="",F597=""),"",IF(F597="학생부종합",INDEX(종합배치표!$C:$Q,MATCH(J597,종합배치표!$B:$B,0),(MATCH(M597,{"A","B","C","D","E"},0)-1)*3+1),INDEX(교과배치표!$C:$Q,MATCH(J597,교과배치표!$B:$B,0),(MATCH(M597,{"A","B","C","D","E"},0)-1)*3+1))),"")} -> 2.7 | S597: {=IFERROR(IF(OR(J597="",M597="",F597=""),"",IF(F597="학생부종합",INDEX(종합배치표!$C:$Q,MATCH(J597,종합배치표!$B:$B,0),(MATCH(M597,{"A","B","C","D","E"},0)-1)*3+2),INDEX(교과배치표!$C:$Q,MATCH(J597,교과배치표!$B:$B,0),(MATCH(M597,{"A","B","C","D","E"},0)-1)*3+2))),"")} -> 2.3 | T597: {=IFERROR(IF(OR(J597="",M597="",F597=""),"",IF(F597="학생부종합",INDEX(종합배치표!$C:$Q,MATCH(J597,종합배치표!$B:$B,0),(MATCH(M597,{"A","B","C","D","E"},0)-1)*3+3),INDEX(교과배치표!$C:$Q,MATCH(J597,교과배치표!$B:$B,0),(MATCH(M597,{"A","B","C","D","E"},0)-1)*3+3))),"")} -> 2 | V597: =$W$2 -> 2.7 | W597: =IF(OR(J597="",V597="",M597=""),"",IF(V597<=T597,"안정",IF(V597<=S597,"적정",IF(V597<=R597,"소신","상향")))) -> 소신
B598: 3633 | C598: 서울 | D598: 서울 | E598: 연세대학교 | F598: 학생부종합 | G598: 활동우수형전형 | H598: 행정학과 | I598: 인문 | J598: 연세활동인문2 | K598: 16 | M598: =IF(I598="","",IF(I598="인문",성적입력!$C$8,성적입력!$C$9)) -> A | N598: =성적입력!$C$15 -> 3 | P598: =IF(OR(J598="",N598="",M598=""),"",IF(N598<=T598,"안정",IF(N598<=S598,"적정",IF(N598<=R598,"소신","상향")))) -> 상향 | R598: {=IFERROR(IF(OR(J598="",M598="",F598=""),"",IF(F598="학생부종합",INDEX(종합배치표!$C:$Q,MATCH(J598,종합배치표!$B:$B,0),(MATCH(M598,{"A","B","C","D","E"},0)-1)*3+1),INDEX(교과배치표!$C:$Q,MATCH(J598,교과배치표!$B:$B,0),(MATCH(M598,{"A","B","C","D","E"},0)-1)*3+1))),"")} -> 2.7 | S598: {=IFERROR(IF(OR(J598="",M598="",F598=""),"",IF(F598="학생부종합",INDEX(종합배치표!$C:$Q,MATCH(J598,종합배치표!$B:$B,0),(MATCH(M598,{"A","B","C","D","E"},0)-1)*3+2),INDEX(교과배치표!$C:$Q,MATCH(J598,교과배치표!$B:$B,0),(MATCH(M598,{"A","B","C","D","E"},0)-1)*3+2))),"")} -> 2.3 | T598: {=IFERROR(IF(OR(J598="",M598="",F598=""),"",IF(F598="학생부종합",INDEX(종합배치표!$C:$Q,MATCH(J598,종합배치표!$B:$B,0),(MATCH(M598,{"A","B","C","D","E"},0)-1)*3+3),INDEX(교과배치표!$C:$Q,MATCH(J598,교과배치표!$B:$B,0),(MATCH(M598,{"A","B","C","D","E"},0)-1)*3+3))),"")} -> 2 | V598: =$W$2 -> 2.7 | W598: =IF(OR(J598="",V598="",M598=""),"",IF(V598<=T598,"안정",IF(V598<=S598,"적정",IF(V598<=R598,"소신","상향")))) -> 소신
B599: 3523 | C599: 서울 | D599: 서울 | E599: 연세대학교 | F599: 학생부종합 | G599: 활동우수형전형 | H599: 국어국문학과 | I599: 인문 | J599: 연세활동인문3 | K599: 10 | M599: =IF(I599="","",IF(I599="인문",성적입력!$C$8,성적입력!$C$9)) -> A | N599: =성적입력!$C$15 -> 3 | P599: =IF(OR(J599="",N599="",M599=""),"",IF(N599<=T599,"안정",IF(N599<=S599,"적정",IF(N599<=R599,"소신","상향")))) -> 상향 | R599: {=IFERROR(IF(OR(J599="",M599="",F599=""),"",IF(F599="학생부종합",INDEX(종합배치표!$C:$Q,MATCH(J599,종합배치표!$B:$B,0),(MATCH(M599,{"A","B","C","D","E"},0)-1)*3+1),INDEX(교과배치표!$C:$Q,MATCH(J599,교과배치표!$B:$B,0),(MATCH(M599,{"A","B","C","D","E"},0)-1)*3+1))),"")} -> 2.8 | S599: {=IFERROR(IF(OR(J599="",M599="",F599=""),"",IF(F599="학생부종합",INDEX(종합배치표!$C:$Q,MATCH(J599,종합배치표!$B:$B,0),(MATCH(M599,{"A","B","C","D","E"},0)-1)*3+2),INDEX(교과배치표!$C:$Q,MATCH(J599,교과배치표!$B:$B,0),(MATCH(M599,{"A","B","C","D","E"},0)-1)*3+2))),"")} -> 2.4 | T599: {=IFERROR(IF(OR(J599="",M599="",F599=""),"",IF(F599="학생부종합",INDEX(종합배치표!$C:$Q,MATCH(J599,종합배치표!$B:$B,0),(MATCH(M599,{"A","B","C","D","E"},0)-1)*3+3),INDEX(교과배치표!$C:$Q,MATCH(J599,교과배치표!$B:$B,0),(MATCH(M599,{"A","B","C","D","E"},0)-1)*3+3))),"")} -> 2.1 | V599: =$W$2 -> 2.7 | W599: =IF(OR(J599="",V599="",M599=""),"",IF(V599<=T599,"안정",IF(V599<=S599,"적정",IF(V599<=R599,"소신","상향")))) -> 소신
B600: 3528 | C600: 서울 | D600: 서울 | E600: 연세대학교 | F600: 학생부종합 | G600: 활동우수형전형 | H600: 노어노문학과 | I600: 인문 | J600: 연세활동인문3 | K600: 6 | M600: =IF(I600="","",IF(I600="인문",성적입력!$C$8,성적입력!$C$9)) -> A | N600: =성적입력!$C$15 -> 3 | P600: =IF(OR(J600="",N600="",M600=""),"",IF(N600<=T600,"안정",IF(N600<=S600,"적정",IF(N600<=R600,"소신","상향")))) -> 상향 | R600: {=IFERROR(IF(OR(J600="",M600="",F600=""),"",IF(F600="학생부종합",INDEX(종합배치표!$C:$Q,MATCH(J600,종합배치표!$B:$B,0),(MATCH(M600,{"A","B","C","D","E"},0)-1)*3+1),INDEX(교과배치표!$C:$Q,MATCH(J600,교과배치표!$B:$B,0),(MATCH(M600,{"A","B","C","D","E"},0)-1)*3+1))),"")} -> 2.8 | S600: {=IFERROR(IF(OR(J600="",M600="",F600=""),"",IF(F600="학생부종합",INDEX(종합배치표!$C:$Q,MATCH(J600,종합배치표!$B:$B,0),(MATCH(M600,{"A","B","C","D","E"},0)-1)*3+2),INDEX(교과배치표!$C:$Q,MATCH(J600,교과배치표!$B:$B,0),(MATCH(M600,{"A","B","C","D","E"},0)-1)*3+2))),"")} -> 2.4 | T600: {=IFERROR(IF(OR(J600="",M600="",F600=""),"",IF(F600="학생부종합",INDEX(종합배치표!$C:$Q,MATCH(J600,종합배치표!$B:$B,0),(MATCH(M600,{"A","B","C","D","E"},0)-1)*3+3),INDEX(교과배치표!$C:$Q,MATCH(J600,교과배치표!$B:$B,0),(MATCH(M600,{"A","B","C","D","E"},0)-1)*3+3))),"")} -> 2.1 | V600: =$W$2 -> 2.7 | W600: =IF(OR(J600="",V600="",M600=""),"",IF(V600<=T600,"안정",IF(V600<=S600,"적정",IF(V600<=R600,"소신","상향")))) -> 소신
B601: 3534 | C601: 서울 | D601: 서울 | E601: 연세대학교 | F601: 학생부종합 | G601: 활동우수형전형 | H601: 독어독문학과 | I601: 인문 | J601: 연세활동인문3 | K601: 6 | M601: =IF(I601="","",IF(I601="인문",성적입력!$C$8,성적입력!$C$9)) -> A | N601: =성적입력!$C$15 -> 3 | P601: =IF(OR(J601="",N601="",M601=""),"",IF(N601<=T601,"안정",IF(N601<=S601,"적정",IF(N601<=R601,"소신","상향")))) -> 상향 | R601: {=IFERROR(IF(OR(J601="",M601="",F601=""),"",IF(F601="학생부종합",INDEX(종합배치표!$C:$Q,MATCH(J601,종합배치표!$B:$B,0),(MATCH(M601,{"A","B","C","D","E"},0)-1)*3+1),INDEX(교과배치표!$C:$Q,MATCH(J601,교과배치표!$B:$B,0),(MATCH(M601,{"A","B","C","D","E"},0)-1)*3+1))),"")} -> 2.8 | S601: {=IFERROR(IF(OR(J601="",M601="",F601=""),"",IF(F601="학생부종합",INDEX(종합배치표!$C:$Q,MATCH(J601,종합배치표!$B:$B,0),(MATCH(M601,{"A","B","C","D","E"},0)-1)*3+2),INDEX(교과배치표!$C:$Q,MATCH(J601,교과배치표!$B:$B,0),(MATCH(M601,{"A","B","C","D","E"},0)-1)*3+2))),"")} -> 2.4 | T601: {=IFERROR(IF(OR(J601="",M601="",F601=""),"",IF(F601="학생부종합",INDEX(종합배치표!$C:$Q,MATCH(J601,종합배치표!$B:$B,0),(MATCH(M601,{"A","B","C","D","E"},0)-1)*3+3),INDEX(교과배치표!$C:$Q,MATCH(J601,교과배치표!$B:$B,0),(MATCH(M601,{"A","B","C","D","E"},0)-1)*3+3))),"")} -> 2.1 | V601: =$W$2 -> 2.7 | W601: =IF(OR(J601="",V601="",M601=""),"",IF(V601<=T601,"안정",IF(V601<=S601,"적정",IF(V601<=R601,"소신","상향")))) -> 소신
... B633: 3617 | C633: 서울 | D633: 서울 | E633: 연세대학교 | F633: 학생부종합 | G633: 활동우수형전형 | H633: 진리자유학부(자연) | I633: 자연 | J633: 연세활동자전자연 | K633: 27 | M633: =IF(I633="","",IF(I633="인문",성적입력!$C$8,성적입력!$C$9)) -> A | N633: =성적입력!$C$15 -> 3 | P633: =IF(OR(J633="",N633="",M633=""),"",IF(N633<=T633,"안정",IF(N633<=S633,"적정",IF(N633<=R633,"소신","상향")))) -> 안정 | R633: {=IFERROR(IF(OR(J633="",M633="",F633=""),"",IF(F633="학생부종합",INDEX(종합배치표!$C:$Q,MATCH(J633,종합배치표!$B:$B,0),(MATCH(M633,{"A","B","C","D","E"},0)-1)*3+1),INDEX(교과배치표!$C:$Q,MATCH(J633,교과배치표!$B:$B,0),(MATCH(M633,{"A","B","C","D","E"},0)-1)*3+1))),"")} | S633: {=IFERROR(IF(OR(J633="",M633="",F633=""),"",IF(F633="학생부종합",INDEX(종합배치표!$C:$Q,MATCH(J633,종합배치표!$B:$B,0),(MATCH(M633,{"A","B","C","D","E"},0)-1)*3+2),INDEX(교과배치표!$C:$Q,MATCH(J633,교과배치표!$B:$B,0),(MATCH(M633,{"A","B","C","D","E"},0)-1)*3+2))),"")} | T633: {=IFERROR(IF(OR(J633="",M633="",F633=""),"",IF(F633="학생부종합",INDEX(종합배치표!$C:$Q,MATCH(J633,종합배치표!$B:$B,0),(MATCH(M633,{"A","B","C","D","E"},0)-1)*3+3),INDEX(교과배치표!$C:$Q,MATCH(J633,교과배치표!$B:$B,0),(MATCH(M633,{"A","B","C","D","E"},0)-1)*3+3))),"")} | V633: =$W$2 -> 2.7 | W633: =IF(OR(J633="",V633="",M633=""),"",IF(V633<=T633,"안정",IF(V633<=S633,"적정",IF(V633<=R633,"소신","상향")))) -> 안정
B634: 1 | C634: 대구 | D634: 대구 | E634: DGIST | F634: 학생부종합 | G634: 일반전형 | H634: 기초학부 | I634: 자연 | K634: 100 | M634: =IF(I634="","",IF(I634="인문",성적입력!$C$8,성적입력!$C$9)) -> A | N634: =성적입력!$C$15 -> 3 | P634: =IF(OR(J634="",N634="",M634=""),"",IF(N634<=T634,"안정",IF(N634<=S634,"적정",IF(N634<=R634,"소신","상향")))) | R634: {=IFERROR(IF(OR(J634="",M634="",F634=""),"",IF(F634="학생부종합",INDEX(종합배치표!$C:$Q,MATCH(J634,종합배치표!$B:$B,0),(MATCH(M634,{"A","B","C","D","E"},0)-1)*3+1),INDEX(교과배치표!$C:$Q,MATCH(J634,교과배치표!$B:$B,0),(MATCH(M634,{"A","B","C","D","E"},0)-1)*3+1))),"")} | S634: {=IFERROR(IF(OR(J634="",M634="",F634=""),"",IF(F634="학생부종합",INDEX(종합배치표!$C:$Q,MATCH(J634,종합배치표!$B:$B,0),(MATCH(M634,{"A","B","C","D","E"},0)-1)*3+2),INDEX(교과배치표!$C:$Q,MATCH(J634,교과배치표!$B:$B,0),(MATCH(M634,{"A","B","C","D","E"},0)-1)*3+2))),"")} | T634: {=IFERROR(IF(OR(J634="",M634="",F634=""),"",IF(F634="학생부종합",INDEX(종합배치표!$C:$Q,MATCH(J634,종합배치표!$B:$B,0),(MATCH(M634,{"A","B","C","D","E"},0)-1)*3+3),INDEX(교과배치표!$C:$Q,MATCH(J634,교과배치표!$B:$B,0),(MATCH(M634,{"A","B","C","D","E"},0)-1)*3+3))),"")} | V634: =$W$2 -> 2.7 | W634: =IF(OR(J634="",V634="",M634=""),"",IF(V634<=T634,"안정",IF(V634<=S634,"적정",IF(V634<=R634,"소신","상향"))))
B635: 2 | C635: 대구 | D635: 대구 | E635: DGIST | F635: 학생부종합 | G635: 학교장추천전형 | H635: 기초학부 | I635: 자연 | K635: 65 | M635: =IF(I635="","",IF(I635="인문",성적입력!$C$8,성적입력!$C$9)) -> A | N635: =성적입력!$C$15 -> 3 | P635: =IF(OR(J635="",N635="",M635=""),"",IF(N635<=T635,"안정",IF(N635<=S635,"적정",IF(N635<=R635,"소신","상향")))) | R635: {=IFERROR(IF(OR(J635="",M635="",F635=""),"",IF(F635="학생부종합",INDEX(종합배치표!$C:$Q,MATCH(J635,종합배치표!$B:$B,0),(MATCH(M635,{"A","B","C","D","E"},0)-1)*3+1),INDEX(교과배치표!$C:$Q,MATCH(J635,교과배치표!$B:$B,0),(MATCH(M635,{"A","B","C","D","E"},0)-1)*3+1))),"")} | S635: {=IFERROR(IF(OR(J635="",M635="",F635=""),"",IF(F635="학생부종합",INDEX(종합배치표!$C:$Q,MATCH(J635,종합배치표!$B:$B,0),(MATCH(M635,{"A","B","C","D","E"},0)-1)*3+2),INDEX(교과배치표!$C:$Q,MATCH(J635,교과배치표!$B:$B,0),(MATCH(M635,{"A","B","C","D","E"},0)-1)*3+2))),"")} | T635: {=IFERROR(IF(OR(J635="",M635="",F635=""),"",IF(F635="학생부종합",INDEX(종합배치표!$C:$Q,MATCH(J635,종합배치표!$B:$B,0),(MATCH(M635,{"A","B","C","D","E"},0)-1)*3+3),INDEX(교과배치표!$C:$Q,MATCH(J635,교과배치표!$B:$B,0),(MATCH(M635,{"A","B","C","D","E"},0)-1)*3+3))),"")} | V635: =$W$2 -> 2.7 | W635: =IF(OR(J635="",V635="",M635=""),"",IF(V635<=T635,"안정",IF(V635<=S635,"적정",IF(V635<=R635,"소신","상향"))))
B636: 3 | C636: 대구 | D636: 대구 | E636: DGIST | F636: 학생부종합 | G636: 일반전형 | H636: 반도체공학과(학석사통합) | I636: 자연 | K636: 15 | M636: =IF(I636="","",IF(I636="인문",성적입력!$C$8,성적입력!$C$9)) -> A | N636: =성적입력!$C$15 -> 3 | P636: =IF(OR(J636="",N636="",M636=""),"",IF(N636<=T636,"안정",IF(N636<=S636,"적정",IF(N636<=R636,"소신","상향")))) | R636: {=IFERROR(IF(OR(J636="",M636="",F636=""),"",IF(F636="학생부종합",INDEX(종합배치표!$C:$Q,MATCH(J636,종합배치표!$B:$B,0),(MATCH(M636,{"A","B","C","D","E"},0)-1)*3+1),INDEX(교과배치표!$C:$Q,MATCH(J636,교과배치표!$B:$B,0),(MATCH(M636,{"A","B","C","D","E"},0)-1)*3+1))),"")} | S636: {=IFERROR(IF(OR(J636="",M636="",F636=""),"",IF(F636="학생부종합",INDEX(종합배치표!$C:$Q,MATCH(J636,종합배치표!$B:$B,0),(MATCH(M636,{"A","B","C","D","E"},0)-1)*3+2),INDEX(교과배치표!$C:$Q,MATCH(J636,교과배치표!$B:$B,0),(MATCH(M636,{"A","B","C","D","E"},0)-1)*3+2))),"")} | T636: {=IFERROR(IF(OR(J636="",M636="",F636=""),"",IF(F636="학생부종합",INDEX(종합배치표!$C:$Q,MATCH(J636,종합배치표!$B:$B,0),(MATCH(M636,{"A","B","C","D","E"},0)-1)*3+3),INDEX(교과배치표!$C:$Q,MATCH(J636,교과배치표!$B:$B,0),(MATCH(M636,{"A","B","C","D","E"},0)-1)*3+3))),"")} | V636: =$W$2 -> 2.7 | W636: =IF(OR(J636="",V636="",M636=""),"",IF(V636<=T636,"안정",IF(V636<=S636,"적정",IF(V636<=R636,"소신","상향"))))
B637: 4 | C637: 대구 | D637: 대구 | E637: DGIST | F637: 학생부종합 | G637: 학교장추천전형 | H637: 반도체공학과(학석사통합) | I637: 자연 | K637: 12 | M637: =IF(I637="","",IF(I637="인문",성적입력!$C$8,성적입력!$C$9)) -> A | N637: =성적입력!$C$15 -> 3 | P637: =IF(OR(J637="",N637="",M637=""),"",IF(N637<=T637,"안정",IF(N637<=S637,"적정",IF(N637<=R637,"소신","상향")))) | R637: {=IFERROR(IF(OR(J637="",M637="",F637=""),"",IF(F637="학생부종합",INDEX(종합배치표!$C:$Q,MATCH(J637,종합배치표!$B:$B,0),(MATCH(M637,{"A","B","C","D","E"},0)-1)*3+1),INDEX(교과배치표!$C:$Q,MATCH(J637,교과배치표!$B:$B,0),(MATCH(M637,{"A","B","C","D","E"},0)-1)*3+1))),"")} | S637: {=IFERROR(IF(OR(J637="",M637="",F637=""),"",IF(F637="학생부종합",INDEX(종합배치표!$C:$Q,MATCH(J637,종합배치표!$B:$B,0),(MATCH(M637,{"A","B","C","D","E"},0)-1)*3+2),INDEX(교과배치표!$C:$Q,MATCH(J637,교과배치표!$B:$B,0),(MATCH(M637,{"A","B","C","D","E"},0)-1)*3+2))),"")} | T637: {=IFERROR(IF(OR(J637="",M637="",F637=""),"",IF(F637="학생부종합",INDEX(종합배치표!$C:$Q,MATCH(J637,종합배치표!$B:$B,0),(MATCH(M637,{"A","B","C","D","E"},0)-1)*3+3),INDEX(교과배치표!$C:$Q,MATCH(J637,교과배치표!$B:$B,0),(MATCH(M637,{"A","B","C","D","E"},0)-1)*3+3))),"")} | V637: =$W$2 -> 2.7 | W637: =IF(OR(J637="",V637="",M637=""),"",IF(V637<=T637,"안정",IF(V637<=S637,"적정",IF(V637<=R637,"소신","상향"))))
B638: 5 | C638: 광주 | D638: 광주 | E638: GIST | F638: 학생부종합 | G638: 일반전형 | H638: 단일계열 | I638: 자연 | K638: 125 | M638: =IF(I638="","",IF(I638="인문",성적입력!$C$8,성적입력!$C$9)) -> A | N638: =성적입력!$C$15 -> 3 | P638: =IF(OR(J638="",N638="",M638=""),"",IF(N638<=T638,"안정",IF(N638<=S638,"적정",IF(N638<=R638,"소신","상향")))) | R638: {=IFERROR(IF(OR(J638="",M638="",F638=""),"",IF(F638="학생부종합",INDEX(종합배치표!$C:$Q,MATCH(J638,종합배치표!$B:$B,0),(MATCH(M638,{"A","B","C","D","E"},0)-1)*3+1),INDEX(교과배치표!$C:$Q,MATCH(J638,교과배치표!$B:$B,0),(MATCH(M638,{"A","B","C","D","E"},0)-1)*3+1))),"")} | S638: {=IFERROR(IF(OR(J638="",M638="",F638=""),"",IF(F638="학생부종합",INDEX(종합배치표!$C:$Q,MATCH(J638,종합배치표!$B:$B,0),(MATCH(M638,{"A","B","C","D","E"},0)-1)*3+2),INDEX(교과배치표!$C:$Q,MATCH(J638,교과배치표!$B:$B,0),(MATCH(M638,{"A","B","C","D","E"},0)-1)*3+2))),"")} | T638: {=IFERROR(IF(OR(J638="",M638="",F638=""),"",IF(F638="학생부종합",INDEX(종합배치표!$C:$Q,MATCH(J638,종합배치표!$B:$B,0),(MATCH(M638,{"A","B","C","D","E"},0)-1)*3+3),INDEX(교과배치표!$C:$Q,MATCH(J638,교과배치표!$B:$B,0),(MATCH(M638,{"A","B","C","D","E"},0)-1)*3+3))),"")} | V638: =$W$2 -> 2.7 | W638: =IF(OR(J638="",V638="",M638=""),"",IF(V638<=T638,"안정",IF(V638<=S638,"적정",IF(V638<=R638,"소신","상향"))))
...

Sheet 성적입력
B2: 성적 입력
B4: 학교 정보 | E4: 생기부
B5: 시도 | C5: 서울 | E5: 학업역량
B6: 행정구 | C6: 서초구 | E6: 진로역량
B7: 학교명 | C7: 세화고등학교 | E7: 공동체역량
B8: 인문랭크 | C8: {=IFERROR(INDEX(고등학교DB!K:K,MATCH(C5&C6&C7,고등학교DB!A:A&고등학교DB!B:B&고등학교DB!G:G,0)),"")} -> A | E8: 주력 계열
B9: 자연랭크 | C9: {=IFERROR(INDEX(고등학교DB!L:L,MATCH(C5&C6&C7,고등학교DB!A:A&고등학교DB!B:B&고등학교DB!G:G,0)),"")} -> A
B11: 내신 성적 | E11: 모의고사 등급
B12: 구분 | C12: 등급 | E12: 과목 | F12: 등급
B13: 국수영사 | C13: 2.3154 | E13: 국어
B14: 국수영과 | C14: 2.28 | E14: 미적분
B15: 국수영사과 | C15: 3 | E15: 확률과통계
B16: 국어 | C16: 2.28 | E16: 영어
B17: 수학 | C17: 2.28 | E17: 한국사
B18: 영어 | C18: 2.28 | E18: 사탐1
B19: 사회 | C19: 2.28 | E19: 사탐2
B20: 과학 | C20: 2.28 | E20: 과탐1
E21: 과탐2

Sheet 종합배치표
B1: 종합전형 내신컷 배치표
B3: 서울일반 | S3: 안정 | T3: 80%~ | U3: 사실상 안정. 어드바이저들이 1~2장 무조건 끼게끔
C4: A | F4: B | I4: C | L4: D | O4: E | S4: 적정 | T4: 50~80% | U4: 특이사항없으면 추가합격하는 느낌의 카드들
B5: 학과유형 | C5: 소신 | D5: 적정 | E5: 안정 | F5: 소신 | G5: 적정 | H5: 안정 | I5: 소신 | J5: 적정 | K5: 안정 | L5: 소신 | M5: 적정 | N5: 안정 | O5: 소신 | P5: 적정 | Q5: 안정 | S5: 소신 | T5: 20~50% | U5: 추가합격 끝자락 느낌이지만 보수적으로 불합격 예측. 어디가 70% 이하 컷
B6: =B$3&"인문1" -> 서울일반인문1 | C6: =IF(D6="","",D6+종합보정값!C$14) -> 2.27 | D6: =IFERROR(IF(INDEX(종합보정값!$C:$C,MATCH(SUBSTITUTE($B6,"인문1","인문2"),종합보정값!$B:$B,0))="","",INDEX(종합보정값!$C:$C,MATCH(SUBSTITUTE($B6,"인문1","인문2"),종합보정값!$B:$B,0))+종합보정값!C$6-종합보정값!C$35),"") -> 1.97 | E6: =IF(D6="","",D6+종합보정값!D$14) -> 1.67 | F6: =IF(G6="","",G6+종합보정값!C$15) -> 1.7 | G6: =IFERROR(IF(INDEX(종합보정값!$C:$C,MATCH(SUBSTITUTE($B6,"인문1","인문2"),종합보정값!$B:$B,0))="","",INDEX(종합보정값!$C:$C,MATCH(SUBSTITUTE($B6,"인문1","인문2"),종합보정값!$B:$B,0))+종합보정값!C$7-종합보정값!C$36),"") -> 1.5 | H6: =IF(G6="","",G6+종합보정값!D$15) -> 1.3 | I6: =IF(J6="","",J6+종합보정값!C$16) -> 1.07 | J6: =IFERROR(IF(INDEX(종합보정값!$C:$C,MATCH(SUBSTITUTE($B6,"인문1","인문2"),종합보정값!$B:$B,0))="","",INDEX(종합보정값!$C:$C,MATCH(SUBSTITUTE($B6,"인문1","인문2"),종합보정값!$B:$B,0))+종합보정값!C$8-종합보정값!C$37),"") -> 1.02 | K6: =IF(J6="","",J6+종합보정값!D$16) -> 0.97 | L6: =IF(M6="","",M6+종합보정값!C$17) -> 1.02 | M6: =IFERROR(IF(INDEX(종합보정값!$C:$C,MATCH(SUBSTITUTE($B6,"인문1","인문2"),종합보정값!$B:$B,0))="","",INDEX(종합보정값!$C:$C,MATCH(SUBSTITUTE($B6,"인문1","인문2"),종합보정값!$B:$B,0))+종합보정값!C$9-종합보정값!C$38),"") -> 0.97 | N6: =IF(M6="","",M6+종합보정값!D$17) -> 0.92 | O6: =IF(P6="","",P6+종합보정값!C$18) -> 0.97 | P6: =IFERROR(IF(INDEX(종합보정값!$C:$C,MATCH(SUBSTITUTE($B6,"인문1","인문2"),종합보정값!$B:$B,0))="","",INDEX(종합보정값!$C:$C,MATCH(SUBSTITUTE($B6,"인문1","인문2"),종합보정값!$B:$B,0))+종합보정값!C$10-종합보정값!C$39),"") -> 0.92 | Q6: =IF(P6="","",P6+종합보정값!D$18) -> 0.87 | S6: 상향 | T6: 0~20% | U6: 펑크나면 붙을텐데 권장하지 않는다
B7: =B$3&"인문2" -> 서울일반인문2 | C7: =IF(D7="","",D7+종합보정값!C$14) -> 2.37 | D7: =IFERROR(IF(INDEX(종합보정값!$C:$C,MATCH($B7,종합보정값!$B:$B,0))="","",INDEX(종합보정값!$C:$C,MATCH($B7,종합보정값!$B:$B,0))+IF(INDEX(종합보정값!$E:$E,MATCH($B7,종합보정값!$B:$B,0))="인문",종합보정값!C$6,종합보정값!D$6)),"") -> 2.07 | E7: =IF(D7="","",D7+종합보정값!D$14) -> 1.77 | F7: =IF(G7="","",G7+종합보정값!C$15) -> 1.77 | G7: =IFERROR(IF(INDEX(종합보정값!$C:$C,MATCH($B7,종합보정값!$B:$B,0))="","",INDEX(종합보정값!$C:$C,MATCH($B7,종합보정값!$B:$B,0))+IF(INDEX(종합보정값!$E:$E,MATCH($B7,종합보정값!$B:$B,0))="인문",종합보정값!C$7,종합보정값!D$7)),"") -> 1.57 | H7: =IF(G7="","",G7+종합보정값!D$15) -> 1.37 | I7: =IF(J7="","",J7+종합보정값!C$16) -> 1.12 | J7: =IFERROR(IF(INDEX(종합보정값!$C:$C,MATCH($B7,종합보정값!$B:$B,0))="","",INDEX(종합보정값!$C:$C,MATCH($B7,종합보정값!$B:$B,0))+IF(INDEX(종합보정값!$E:$E,MATCH($B7,종합보정값!$B:$B,0))="인문",종합보정값!C$8,종합보정값!D$8)),"") -> 1.07 | K7: =IF(J7="","",J7+종합보정값!D$16) -> 1.02 | L7: =IF(M7="","",M7+종합보정값!C$17) -> 1.07 | M7: =IFERROR(IF(INDEX(종합보정값!$C:$C,MATCH($B7,종합보정값!$B:$B,0))="","",INDEX(종합보정값!$C:$C,MATCH($B7,종합보정값!$B:$B,0))+IF(INDEX(종합보정값!$E:$E,MATCH($B7,종합보정값!$B:$B,0))="인문",종합보정값!C$9,종합보정값!D$9)),"") -> 1.02 | N7: =IF(M7="","",M7+종합보정값!D$17) -> 0.97 | O7: =IF(P7="","",P7+종합보정값!C$18) -> 1.02 | P7: =IFERROR(IF(INDEX(종합보정값!$C:$C,MATCH($B7,종합보정값!$B:$B,0))="","",INDEX(종합보정값!$C:$C,MATCH($B7,종합보정값!$B:$B,0))+IF(INDEX(종합보정값!$E:$E,MATCH($B7,종합보정값!$B:$B,0))="인문",종합보정값!C$10,종합보정값!D$10)),"") -> 0.97 | Q7: =IF(P7="","",P7+종합보정값!D$18) -> 0.92
B8: =B$3&"인문3" -> 서울일반인문3 | C8: =IF(D8="","",D8+종합보정값!C$14) -> 2.47 | D8: =IFERROR(IF(INDEX(종합보정값!$C:$C,MATCH(SUBSTITUTE($B8,"인문3","인문2"),종합보정값!$B:$B,0))="","",INDEX(종합보정값!$C:$C,MATCH(SUBSTITUTE($B8,"인문3","인문2"),종합보정값!$B:$B,0))+종합보정값!C$6+종합보정값!C$35),"") -> 2.17 | E8: =IF(D8="","",D8+종합보정값!D$14) -> 1.87 | F8: =IF(G8="","",G8+종합보정값!C$15) -> 1.84 | G8: =IFERROR(IF(INDEX(종합보정값!$C:$C,MATCH(SUBSTITUTE($B8,"인문3","인문2"),종합보정값!$B:$B,0))="","",INDEX(종합보정값!$C:$C,MATCH(SUBSTITUTE($B8,"인문3","인문2"),종합보정값!$B:$B,0))+종합보정값!C$7+종합보정값!C$36),"") -> 1.64 | H8: =IF(G8="","",G8+종합보정값!D$15) -> 1.44 | I8: =IF(J8="","",J8+종합보정값!C$16) -> 1.17 | J8: =IFERROR(IF(INDEX(종합보정값!$C:$C,MATCH(SUBSTITUTE($B8,"인문3","인문2"),종합보정값!$B:$B,0))="","",INDEX(종합보정값!$C:$C,MATCH(SUBSTITUTE($B8,"인문3","인문2"),종합보정값!$B:$B,0))+종합보정값!C$8+종합보정값!C$37),"") -> 1.12 | K8: =IF(J8="","",J8+종합보정값!D$16) -> 1.07 | L8: =IF(M8="","",M8+종합보정값!C$17) -> 1.12 | M8: =IFERROR(IF(INDEX(종합보정값!$C:$C,MATCH(SUBSTITUTE($B8,"인문3","인문2"),종합보정값!$B:$B,0))="","",INDEX(종합보정값!$C:$C,MATCH(SUBSTITUTE($B8,"인문3","인문2"),종합보정값!$B:$B,0))+종합보정값!C$9+종합보정값!C$38),"") -> 1.07 | N8: =IF(M8="","",M8+종합보정값!D$17) -> 1.02 | O8: =IF(P8="","",P8+종합보정값!C$18) -> 1.07 | P8: =IFERROR(IF(INDEX(종합보정값!$C:$C,MATCH(SUBSTITUTE($B8,"인문3","인문2"),종합보정값!$B:$B,0))="","",INDEX(종합보정값!$C:$C,MATCH(SUBSTITUTE($B8,"인문3","인문2"),종합보정값!$B:$B,0))+종합보정값!C$10+종합보정값!C$39),"") -> 1.02 | Q8: =IF(P8="","",P8+종합보정값!D$18) -> 0.97
B9: =B$3&"자연1" -> 서울일반자연1 | C9: =IF(D9="","",D9+종합보정값!C$14) -> 3.15 | D9: =IFERROR(IF(INDEX(종합보정값!$C:$C,MATCH(SUBSTITUTE($B9,"자연1","자연2"),종합보정값!$B:$B,0))="","",INDEX(종합보정값!$C:$C,MATCH(SUBSTITUTE($B9,"자연1","자연2"),종합보정값!$B:$B,0))+종합보정값!D$6-종합보정값!D$35),"") -> 2.85 | E9: =IF(D9="","",D9+종합보정값!D$14) -> 2.55 | F9: =IF(G9="","",G9+종합보정값!C$15) -> 2.08 | G9: =IFERROR(IF(INDEX(종합보정값!$C:$C,MATCH(SUBSTITUTE($B9,"자연1","자연2"),종합보정값!$B:$B,0))="","",INDEX(종합보정값!$C:$C,MATCH(SUBSTITUTE($B9,"자연1","자연2"),종합보정값!$B:$B,0))+종합보정값!D$7-종합보정값!D$36),"") -> 1.88 | H9: =IF(G9="","",G9+종합보정값!D$15) -> 1.68 | I9: =IF(J9="","",J9+종합보정값!C$16) -> 1.2 | J9: =IFERROR(IF(INDEX(종합보정값!$C:$C,MATCH(SUBSTITUTE($B9,"자연1","자연2"),종합보정값!$B:$B,0))="","",INDEX(종합보정값!$C:$C,MATCH(SUBSTITUTE($B9,"자연1","자연2"),종합보정값!$B:$B,0))+종합보정값!D$8-종합보정값!D$37),"") -> 1.15 | K9: =IF(J9="","",J9+종합보정값!D$16) -> 1.1 | L9: =IF(M9="","",M9+종합보정값!C$17) -> 1 | M9: =IFERROR(IF(INDEX(종합보정값!$C:$C,MATCH(SUBSTITUTE($B9,"자연1","자연2"),종합보정값!$B:$B,0))="","",INDEX(종합보정값!$C:$C,MATCH(SUBSTITUTE($B9,"자연1","자연2"),종합보정값!$B:$B,0))+종합보정값!D$9-종합보정값!D$38),"") -> 0.95 | N9: =IF(M9="","",M9+종합보정값!D$17) -> 0.9 | O9: =IF(P9="","",P9+종합보정값!C$18) -> 0.95 | P9: =IFERROR(IF(INDEX(종합보정값!$C:$C,MATCH(SUBSTITUTE($B9,"자연1","자연2"),종합보정값!$B:$B,0))="","",INDEX(종합보정값!$C:$C,MATCH(SUBSTITUTE($B9,"자연1","자연2"),종합보정값!$B:$B,0))+종합보정값!D$10-종합보정값!D$39),"") -> 0.9 | Q9: =IF(P9="","",P9+종합보정값!D$18) -> 0.85
B10: =B$3&"자연2" -> 서울일반자연2 | C10: =IF(D10="","",D10+종합보정값!C$14) -> 3.25 | D10: =IFERROR(IF(INDEX(종합보정값!$C:$C,MATCH($B10,종합보정값!$B:$B,0))="","",INDEX(종합보정값!$C:$C,MATCH($B10,종합보정값!$B:$B,0))+IF(INDEX(종합보정값!$E:$E,MATCH($B10,종합보정값!$B:$B,0))="인문",종합보정값!C$6,종합보정값!D$6)),"") -> 2.95 | E10: =IF(D10="","",D10+종합보정값!D$14) -> 2.65 | F10: =IF(G10="","",G10+종합보정값!C$15) -> 2.15 | G10: =IFERROR(IF(INDEX(종합보정값!$C:$C,MATCH($B10,종합보정값!$B:$B,0))="","",INDEX(종합보정값!$C:$C,MATCH($B10,종합보정값!$B:$B,0))+IF(INDEX(종합보정값!$E:$E,MATCH($B10,종합보정값!$B:$B,0))="인문",종합보정값!C$7,종합보정값!D$7)),"") -> 1.95 | H10: =IF(G10="","",G10+종합보정값!D$15) -> 1.75 | I10: =IF(J10="","",J10+종합보정값!C$16) -> 1.25 | J10: =IFERROR(IF(INDEX(종합보정값!$C:$C,MATCH($B10,종합보정값!$B:$B,0))="","",INDEX(종합보정값!$C:$C,MATCH($B10,종합보정값!$B:$B,0))+IF(INDEX(종합보정값!$E:$E,MATCH($B10,종합보정값!$B:$B,0))="인문",종합보정값!C$8,종합보정값!D$8)),"") -> 1.2 | K10: =IF(J10="","",J10+종합보정값!D$16) -> 1.15 | L10: =IF(M10="","",M10+종합보정값!C$17) -> 1.05 | M10: =IFERROR(IF(INDEX(종합보정값!$C:$C,MATCH($B10,종합보정값!$B:$B,0))="","",INDEX(종합보정값!$C:$C,MATCH($B10,종합보정값!$B:$B,0))+IF(INDEX(종합보정값!$E:$E,MATCH($B10,종합보정값!$B:$B,0))="인문",종합보정값!C$9,종합보정값!D$9)),"") -> 1 | N10: =IF(M10="","",M10+종합보정값!D$17) -> 0.95 | O10: =IF(P10="","",P10+종합보정값!C$18) -> 1 | P10: =IFERROR(IF(INDEX(종합보정값!$C:$C,MATCH($B10,종합보정값!$B:$B,0))="","",INDEX(종합보정값!$C:$C,MATCH($B10,종합보정값!$B:$B,0))+IF(INDEX(종합보정값!$E:$E,MATCH($B10,종합보정값!$B:$B,0))="인문",종합보정값!C$10,종합보정값!D$10)),"") -> 0.95 | Q10: =IF(P10="","",P10+종합보정값!D$18) -> 0.9
B11: =B$3&"자연3" -> 서울일반자연3 | C11: =IF(D11="","",D11+종합보정값!C$14) -> 3.35 | D11: =IFERROR(IF(INDEX(종합보정값!$C:$C,MATCH(SUBSTITUTE($B11,"자연3","자연2"),종합보정값!$B:$B,0))="","",INDEX(종합보정값!$C:$C,MATCH(SUBSTITUTE($B11,"자연3","자연2"),종합보정값!$B:$B,0))+종합보정값!D$6+종합보정값!D$35),"") -> 3.05 | E11: =IF(D11="","",D11+종합보정값!D$14) -> 2.75 | F11: =IF(G11="","",G11+종합보정값!C$15) -> 2.22 | G11: =IFERROR(IF(INDEX(종합보정값!$C:$C,MATCH(SUBSTITUTE($B11,"자연3","자연2"),종합보정값!$B:$B,0))="","",INDEX(종합보정값!$C:$C,MATCH(SUBSTITUTE($B11,"자연3","자연2"),종합보정값!$B:$B,0))+종합보정값!D$7+종합보정값!D$36),"") -> 2.02 | H11: =IF(G11="","",G11+종합보정값!D$15) -> 1.82 | I11: =IF(J11="","",J11+종합보정값!C$16) -> 1.3 | J11: =IFERROR(IF(INDEX(종합보정값!$C:$C,MATCH(SUBSTITUTE($B11,"자연3","자연2"),종합보정값!$B:$B,0))="","",INDEX(종합보정값!$C:$C,MATCH(SUBSTITUTE($B11,"자연3","자연2"),종합보정값!$B:$B,0))+종합보정값!D$8+종합보정값!D$37),"") -> 1.25 | K11: =IF(J11="","",J11+종합보정값!D$16) -> 1.2 | L11: =IF(M11="","",M11+종합보정값!C$17) -> 1.1 | M11: =IFERROR(IF(INDEX(종합보정값!$C:$C,MATCH(SUBSTITUTE($B11,"자연3","자연2"),종합보정값!$B:$B,0))="","",INDEX(종합보정값!$C:$C,MATCH(SUBSTITUTE($B11,"자연3","자연2"),종합보정값!$B:$B,0))+종합보정값!D$9+종합보정값!D$38),"") -> 1.05 | N11: =IF(M11="","",M11+종합보정값!D$17) -> 1 | O11: =IF(P11="","",P11+종합보정값!C$18) -> 1.05 | P11: =IFERROR(IF(INDEX(종합보정값!$C:$C,MATCH(SUBSTITUTE($B11,"자연3","자연2"),종합보정값!$B:$B,0))="","",INDEX(종합보정값!$C:$C,MATCH(SUBSTITUTE($B11,"자연3","자연2"),종합보정값!$B:$B,0))+종합보정값!D$10+종합보정값!D$39),"") -> 1 | Q11: =IF(P11="","",P11+종합보정값!D$18) -> 0.95
B12: =B$3&"사범" -> 서울일반사범 | C12: =IF(D12="","",D12+종합보정값!C$14) | D12: =IFERROR(IF(INDEX(종합보정값!$C:$C,MATCH($B12,종합보정값!$B:$B,0))="","",INDEX(종합보정값!$C:$C,MATCH($B12,종합보정값!$B:$B,0))+IF(INDEX(종합보정값!$E:$E,MATCH($B12,종합보정값!$B:$B,0))="인문",종합보정값!C$6,종합보정값!D$6)),"") | E12: =IF(D12="","",D12+종합보정값!D$14) | F12: =IF(G12="","",G12+종합보정값!C$15) | G12: =IFERROR(IF(INDEX(종합보정값!$C:$C,MATCH($B12,종합보정값!$B:$B,0))="","",INDEX(종합보정값!$C:$C,MATCH($B12,종합보정값!$B:$B,0))+IF(INDEX(종합보정값!$E:$E,MATCH($B12,종합보정값!$B:$B,0))="인문",종합보정값!C$7,종합보정값!D$7)),"") | H12: =IF(G12="","",G12+종합보정값!D$15) | I12: =IF(J12="","",J12+종합보정값!C$16) | J12: =IFERROR(IF(INDEX(종합보정값!$C:$C,MATCH($B12,종합보정값!$B:$B,0))="","",INDEX(종합보정값!$C:$C,MATCH($B12,종합보정값!$B:$B,0))+IF(INDEX(종합보정값!$E:$E,MATCH($B12,종합보정값!$B:$B,0))="인문",종합보정값!C$8,종합보정값!D$8)),"") | K12: =IF(J12="","",J12+종합보정값!D$16) | L12: =IF(M12="","",M12+종합보정값!C$17) | M12: =IFERROR(IF(INDEX(종합보정값!$C:$C,MATCH($B12,종합보정값!$B:$B,0))="","",INDEX(종합보정값!$C:$C,MATCH($B12,종합보정값!$B:$B,0))+IF(INDEX(종합보정값!$E:$E,MATCH($B12,종합보정값!$B:$B,0))="인문",종합보정값!C$9,종합보정값!D$9)),"") | N12: =IF(M12="","",M12+종합보정값!D$17) | O12: =IF(P12="","",P12+종합보정값!C$18) | P12: =IFERROR(IF(INDEX(종합보정값!$C:$C,MATCH($B12,종합보정값!$B:$B,0))="","",INDEX(종합보정값!$C:$C,MATCH($B12,종합보정값!$B:$B,0))+IF(INDEX(종합보정값!$E:$E,MATCH($B12,종합보정값!$B:$B,0))="인문",종합보정값!C$10,종합보정값!D$10)),"") | Q12: =IF(P12="","",P12+종합보정값!D$18)
B13: =B$3&"자전자연" -> 서울일반자전자연 | C13: =IF(D13="","",D13+종합보정값!C$14) | D13: =IFERROR(IF(INDEX(종합보정값!$C:$C,MATCH($B13,종합보정값!$B:$B,0))="","",INDEX(종합보정값!$C:$C,MATCH($B13,종합보정값!$B:$B,0))+IF(INDEX(종합보정값!$E:$E,MATCH($B13,종합보정값!$B:$B,0))="인문",종합보정값!C$6,종합보정값!D$6)),"") | E13: =IF(D13="","",D13+종합보정값!D$14) | F13: =IF(G13="","",G13+종합보정값!C$15) | G13: =IFERROR(IF(INDEX(종합보정값!$C:$C,MATCH($B13,종합보정값!$B:$B,0))="","",INDEX(종합보정값!$C:$C,MATCH($B13,종합보정값!$B:$B,0))+IF(INDEX(종합보정값!$E:$E,MATCH($B13,종합보정값!$B:$B,0))="인문",종합보정값!C$7,종합보정값!D$7)),"") | H13: =IF(G13="","",G13+종합보정값!D$15) | I13: =IF(J13="","",J13+종합보정값!C$16) | J13: =IFERROR(IF(INDEX(종합보정값!$C:$C,MATCH($B13,종합보정값!$B:$B,0))="","",INDEX(종합보정값!$C:$C,MATCH($B13,종합보정값!$B:$B,0))+IF(INDEX(종합보정값!$E:$E,MATCH($B13,종합보정값!$B:$B,0))="인문",종합보정값!C$8,종합보정값!D$8)),"") | K13: =IF(J13="","",J13+종합보정값!D$16) | L13: =IF(M13="","",M13+종합보정값!C$17) | M13: =IFERROR(IF(INDEX(종합보정값!$C:$C,MATCH($B13,종합보정값!$B:$B,0))="","",INDEX(종합보정값!$C:$C,MATCH($B13,종합보정값!$B:$B,0))+IF(INDEX(종합보정값!$E:$E,MATCH($B13,종합보정값!$B:$B,0))="인문",종합보정값!C$9,종합보정값!D$9)),"") | N13: =IF(M13="","",M13+종합보정값!D$17) | O13: =IF(P13="","",P13+종합보정값!C$18) | P13: =IFERROR(IF(INDEX(종합보정값!$C:$C,MATCH($B13,종합보정값!$B:$B,0))="","",INDEX(종합보정값!$C:$C,MATCH($B13,종합보정값!$B:$B,0))+IF(INDEX(종합보정값!$E:$E,MATCH($B13,종합보정값!$B:$B,0))="인문",종합보정값!C$10,종합보정값!D$10)),"") | Q13: =IF(P13="","",P13+종합보정값!D$18)
